2019-09-17 03:55:28,867 [WARNING] [/home/ma/PycharmProjects/Auto_InterFace_GUI/venv/lib/python3.6/site-packages/django/utils/log.py] [log_response ][django.request:228]- Not Found: /home/ma/PycharmProjects/Auto_InterFace_GUI/InterfaceTest/static/project_tree/test2/report/20190917/manage20190917035523.html
2019-09-17 05:06:34,925 [INFO] [/home/ma/PycharmProjects/Auto_InterFace_GUI/venv/lib/python3.6/site-packages/django/utils/autoreload.py] [trigger_reload ][django.utils.autoreload:217]- /home/ma/PycharmProjects/Auto_InterFace_GUI/upload_case/views.py changed, reloading.
2019-09-17 05:09:15,554 [WARNING] [/home/ma/PycharmProjects/Auto_InterFace_GUI/venv/lib/python3.6/site-packages/django/utils/log.py] [log_response ][django.request:228]- Not Found: /index/static/project_tree/test6/report/20190917/manage20190917050908.html
2019-09-17 05:12:47,038 [INFO] [/home/ma/PycharmProjects/Auto_InterFace_GUI/venv/lib/python3.6/site-packages/django/utils/autoreload.py] [trigger_reload ][django.utils.autoreload:217]- /home/ma/PycharmProjects/Auto_InterFace_GUI/upload_case/views.py changed, reloading.
2019-09-17 05:14:10,173 [INFO] [/home/ma/PycharmProjects/Auto_InterFace_GUI/venv/lib/python3.6/site-packages/django/utils/autoreload.py] [trigger_reload ][django.utils.autoreload:217]- /home/ma/PycharmProjects/Auto_InterFace_GUI/upload_case/views.py changed, reloading.
2019-09-17 05:16:57,707 [INFO] [/home/ma/PycharmProjects/Auto_InterFace_GUI/venv/lib/python3.6/site-packages/django/utils/autoreload.py] [trigger_reload ][django.utils.autoreload:217]- /home/ma/PycharmProjects/Auto_InterFace_GUI/upload_case/case_test_common.py changed, reloading.
2019-09-17 05:18:47,422 [ERROR] [/home/ma/PycharmProjects/Auto_InterFace_GUI/InterfaceTest/python_excel/utils/operation_json.py] [read_data ][/home/ma/PycharmProjects/Auto_InterFace_GUI/InterfaceTest/python_excel/utils/operation_json.py:25]- 操作JSON类读取数据异常，异常原因：Extra data: line 5 column 2 (char 371)
2019-09-17 05:18:47,422 [ERROR] [/home/ma/PycharmProjects/Auto_InterFace_GUI/InterfaceTest/python_excel/utils/operation_json.py] [read_data ][/home/ma/PycharmProjects/Auto_InterFace_GUI/InterfaceTest/python_excel/utils/operation_json.py:25]- 操作JSON类读取数据异常，异常原因：Extra data: line 5 column 2 (char 371)
2019-09-17 05:18:47,422 [ERROR] [/home/ma/PycharmProjects/Auto_InterFace_GUI/InterfaceTest/python_excel/utils/operation_json.py] [get_data_for_key ][/home/ma/PycharmProjects/Auto_InterFace_GUI/InterfaceTest/python_excel/utils/operation_json.py:39]- 操作JSON类根据key获取value异常，异常原因：'NoneType' object is not subscriptable
2019-09-17 05:18:47,423 [ERROR] [/home/ma/PycharmProjects/Auto_InterFace_GUI/InterfaceTest/python_excel/utils/operation_json.py] [read_data ][/home/ma/PycharmProjects/Auto_InterFace_GUI/InterfaceTest/python_excel/utils/operation_json.py:25]- 操作JSON类读取数据异常，异常原因：Extra data: line 5 column 2 (char 371)
2019-09-17 05:18:47,423 [ERROR] [/home/ma/PycharmProjects/Auto_InterFace_GUI/InterfaceTest/python_excel/utils/operation_json.py] [get_data_for_key ][/home/ma/PycharmProjects/Auto_InterFace_GUI/InterfaceTest/python_excel/utils/operation_json.py:39]- 操作JSON类根据key获取value异常，异常原因：'NoneType' object is not subscriptable
2019-09-17 05:18:47,423 [ERROR] [/home/ma/PycharmProjects/Auto_InterFace_GUI/InterfaceTest/python_excel/utils/operation_json.py] [read_data ][/home/ma/PycharmProjects/Auto_InterFace_GUI/InterfaceTest/python_excel/utils/operation_json.py:25]- 操作JSON类读取数据异常，异常原因：Extra data: line 5 column 2 (char 371)
2019-09-17 05:18:47,423 [ERROR] [/home/ma/PycharmProjects/Auto_InterFace_GUI/InterfaceTest/python_excel/utils/operation_json.py] [get_data_for_key ][/home/ma/PycharmProjects/Auto_InterFace_GUI/InterfaceTest/python_excel/utils/operation_json.py:39]- 操作JSON类根据key获取value异常，异常原因：'NoneType' object is not subscriptable
2019-09-17 05:18:47,423 [ERROR] [/home/ma/PycharmProjects/Auto_InterFace_GUI/InterfaceTest/python_excel/utils/operation_cfg.py] [read_cfg ][__file__:31]- 读取cfg配置文件内容异常，异常原因：'NoneType' object is not iterable
2019-09-17 05:18:47,424 [ERROR] [/home/ma/PycharmProjects/Auto_InterFace_GUI/InterfaceTest/python_excel/utils/operation_cfg.py] [get_section_option_list ][__file__:82]- 读取配置文件指定段section下所有option列表出现异常，异常原因：No section: 'my_case_file'
2019-09-17 05:18:53,055 [ERROR] [/home/ma/PycharmProjects/Auto_InterFace_GUI/venv/lib/python3.6/site-packages/django/utils/log.py] [log_response ][django.request:228]- Internal Server Error: /index/
Traceback (most recent call last):
  File "/home/ma/PycharmProjects/Auto_InterFace_GUI/venv/lib/python3.6/site-packages/django/core/handlers/exception.py", line 34, in inner
    response = get_response(request)
  File "/home/ma/PycharmProjects/Auto_InterFace_GUI/venv/lib/python3.6/site-packages/django/core/handlers/base.py", line 115, in _get_response
    response = self.process_exception_by_middleware(e, request)
  File "/home/ma/PycharmProjects/Auto_InterFace_GUI/venv/lib/python3.6/site-packages/django/core/handlers/base.py", line 113, in _get_response
    response = wrapped_callback(request, *callback_args, **callback_kwargs)
  File "/home/ma/PycharmProjects/Auto_InterFace_GUI/upload_case/views.py", line 29, in index
    from upload_case import case_test_common
  File "/home/ma/PycharmProjects/Auto_InterFace_GUI/upload_case/case_test_common.py", line 37, in <module>
    filename = option_dict["case_filepath"]
KeyError: 'case_filepath'
2019-09-17 05:26:30,563 [INFO] [/home/ma/PycharmProjects/Auto_InterFace_GUI/venv/lib/python3.6/site-packages/django/utils/autoreload.py] [trigger_reload ][django.utils.autoreload:217]- /home/ma/PycharmProjects/Auto_InterFace_GUI/Auto_InterFace_GUI/settings.py changed, reloading.
2019-09-17 13:42:46,887 [INFO] [/home/ma/PycharmProjects/Auto_InterFace_GUI/venv/lib/python3.6/site-packages/django/utils/autoreload.py] [trigger_reload ][django.utils.autoreload:217]- /home/ma/PycharmProjects/Auto_InterFace_GUI/upload_case/views.py changed, reloading.
2019-09-17 13:48:20,198 [ERROR] [/home/ma/PycharmProjects/Auto_InterFace_GUI/InterfaceTest/python_excel/utils/operation_json.py] [read_data ][/home/ma/PycharmProjects/Auto_InterFace_GUI/InterfaceTest/python_excel/utils/operation_json.py:25]- 操作JSON类读取数据异常，异常原因：Extra data: line 5 column 2 (char 371)
2019-09-17 13:48:20,199 [ERROR] [/home/ma/PycharmProjects/Auto_InterFace_GUI/InterfaceTest/python_excel/utils/operation_json.py] [read_data ][/home/ma/PycharmProjects/Auto_InterFace_GUI/InterfaceTest/python_excel/utils/operation_json.py:25]- 操作JSON类读取数据异常，异常原因：Extra data: line 5 column 2 (char 371)
2019-09-17 13:48:20,199 [ERROR] [/home/ma/PycharmProjects/Auto_InterFace_GUI/InterfaceTest/python_excel/utils/operation_json.py] [get_data_for_key ][/home/ma/PycharmProjects/Auto_InterFace_GUI/InterfaceTest/python_excel/utils/operation_json.py:39]- 操作JSON类根据key获取value异常，异常原因：'NoneType' object is not subscriptable
2019-09-17 13:48:20,199 [ERROR] [/home/ma/PycharmProjects/Auto_InterFace_GUI/InterfaceTest/python_excel/utils/operation_json.py] [read_data ][/home/ma/PycharmProjects/Auto_InterFace_GUI/InterfaceTest/python_excel/utils/operation_json.py:25]- 操作JSON类读取数据异常，异常原因：Extra data: line 5 column 2 (char 371)
2019-09-17 13:48:20,200 [ERROR] [/home/ma/PycharmProjects/Auto_InterFace_GUI/InterfaceTest/python_excel/utils/operation_json.py] [get_data_for_key ][/home/ma/PycharmProjects/Auto_InterFace_GUI/InterfaceTest/python_excel/utils/operation_json.py:39]- 操作JSON类根据key获取value异常，异常原因：'NoneType' object is not subscriptable
2019-09-17 13:48:20,200 [ERROR] [/home/ma/PycharmProjects/Auto_InterFace_GUI/InterfaceTest/python_excel/utils/operation_json.py] [read_data ][/home/ma/PycharmProjects/Auto_InterFace_GUI/InterfaceTest/python_excel/utils/operation_json.py:25]- 操作JSON类读取数据异常，异常原因：Extra data: line 5 column 2 (char 371)
2019-09-17 13:48:20,200 [ERROR] [/home/ma/PycharmProjects/Auto_InterFace_GUI/InterfaceTest/python_excel/utils/operation_json.py] [get_data_for_key ][/home/ma/PycharmProjects/Auto_InterFace_GUI/InterfaceTest/python_excel/utils/operation_json.py:39]- 操作JSON类根据key获取value异常，异常原因：'NoneType' object is not subscriptable
2019-09-17 13:48:20,200 [ERROR] [/home/ma/PycharmProjects/Auto_InterFace_GUI/InterfaceTest/python_excel/utils/operation_cfg.py] [read_cfg ][__file__:31]- 读取cfg配置文件内容异常，异常原因：'NoneType' object is not iterable
2019-09-17 13:48:20,201 [ERROR] [/home/ma/PycharmProjects/Auto_InterFace_GUI/InterfaceTest/python_excel/utils/operation_cfg.py] [get_section_option_list ][__file__:82]- 读取配置文件指定段section下所有option列表出现异常，异常原因：No section: 'my_case_file'
2019-09-17 13:48:20,254 [ERROR] [/home/ma/PycharmProjects/Auto_InterFace_GUI/InterfaceTest/python_excel/utils/operation_json.py] [read_data ][/home/ma/PycharmProjects/Auto_InterFace_GUI/InterfaceTest/python_excel/utils/operation_json.py:25]- 操作JSON类读取数据异常，异常原因：Extra data: line 5 column 2 (char 371)
2019-09-17 13:48:20,255 [ERROR] [/home/ma/PycharmProjects/Auto_InterFace_GUI/InterfaceTest/python_excel/utils/operation_json.py] [get_data_for_key ][/home/ma/PycharmProjects/Auto_InterFace_GUI/InterfaceTest/python_excel/utils/operation_json.py:39]- 操作JSON类根据key获取value异常，异常原因：'NoneType' object is not subscriptable
2019-09-17 13:48:20,273 [ERROR] [/home/ma/PycharmProjects/Auto_InterFace_GUI/InterfaceTest/python_excel/utils/operation_json.py] [read_data ][/home/ma/PycharmProjects/Auto_InterFace_GUI/InterfaceTest/python_excel/utils/operation_json.py:25]- 操作JSON类读取数据异常，异常原因：Extra data: line 5 column 2 (char 371)
2019-09-17 13:48:20,273 [ERROR] [/home/ma/PycharmProjects/Auto_InterFace_GUI/InterfaceTest/python_excel/utils/operation_json.py] [get_data_for_key ][/home/ma/PycharmProjects/Auto_InterFace_GUI/InterfaceTest/python_excel/utils/operation_json.py:39]- 操作JSON类根据key获取value异常，异常原因：'NoneType' object is not subscriptable
2019-09-17 13:48:20,278 [ERROR] [/home/ma/PycharmProjects/Auto_InterFace_GUI/InterfaceTest/python_excel/utils/operation_json.py] [read_data ][/home/ma/PycharmProjects/Auto_InterFace_GUI/InterfaceTest/python_excel/utils/operation_json.py:25]- 操作JSON类读取数据异常，异常原因：Extra data: line 5 column 2 (char 371)
2019-09-17 13:48:20,279 [ERROR] [/home/ma/PycharmProjects/Auto_InterFace_GUI/InterfaceTest/python_excel/utils/operation_json.py] [get_data_for_key ][/home/ma/PycharmProjects/Auto_InterFace_GUI/InterfaceTest/python_excel/utils/operation_json.py:39]- 操作JSON类根据key获取value异常，异常原因：'NoneType' object is not subscriptable
2019-09-17 13:48:20,282 [ERROR] [/home/ma/PycharmProjects/Auto_InterFace_GUI/InterfaceTest/python_excel/utils/operation_json.py] [read_data ][/home/ma/PycharmProjects/Auto_InterFace_GUI/InterfaceTest/python_excel/utils/operation_json.py:25]- 操作JSON类读取数据异常，异常原因：Extra data: line 5 column 2 (char 371)
2019-09-17 13:48:20,282 [ERROR] [/home/ma/PycharmProjects/Auto_InterFace_GUI/InterfaceTest/python_excel/utils/operation_json.py] [get_data_for_key ][/home/ma/PycharmProjects/Auto_InterFace_GUI/InterfaceTest/python_excel/utils/operation_json.py:39]- 操作JSON类根据key获取value异常，异常原因：'NoneType' object is not subscriptable
2019-09-17 13:48:20,958 [ERROR] [/home/ma/PycharmProjects/Auto_InterFace_GUI/venv/lib/python3.6/site-packages/django/utils/log.py] [log_response ][django.request:228]- Internal Server Error: /index/
Traceback (most recent call last):
  File "/home/ma/PycharmProjects/Auto_InterFace_GUI/venv/lib/python3.6/site-packages/django/core/handlers/exception.py", line 34, in inner
    response = get_response(request)
  File "/home/ma/PycharmProjects/Auto_InterFace_GUI/venv/lib/python3.6/site-packages/django/core/handlers/base.py", line 115, in _get_response
    response = self.process_exception_by_middleware(e, request)
  File "/home/ma/PycharmProjects/Auto_InterFace_GUI/venv/lib/python3.6/site-packages/django/core/handlers/base.py", line 113, in _get_response
    response = wrapped_callback(request, *callback_args, **callback_kwargs)
  File "/home/ma/PycharmProjects/Auto_InterFace_GUI/upload_case/views.py", line 29, in index
    from upload_case import case_test_common
  File "/home/ma/PycharmProjects/Auto_InterFace_GUI/upload_case/case_test_common.py", line 37, in <module>
    filename = option_dict["case_filepath"]
KeyError: 'case_filepath'
2019-09-17 13:50:33,668 [INFO] [/home/ma/PycharmProjects/Auto_InterFace_GUI/venv/lib/python3.6/site-packages/django/utils/autoreload.py] [trigger_reload ][django.utils.autoreload:217]- /home/ma/PycharmProjects/Auto_InterFace_GUI/upload_case/views.py changed, reloading.
2019-09-17 13:51:58,987 [ERROR] [/home/ma/PycharmProjects/Auto_InterFace_GUI/venv/lib/python3.6/site-packages/django/utils/log.py] [log_response ][django.request:228]- Internal Server Error: /index/
Traceback (most recent call last):
  File "/home/ma/PycharmProjects/Auto_InterFace_GUI/venv/lib/python3.6/site-packages/django/core/handlers/exception.py", line 34, in inner
    response = get_response(request)
  File "/home/ma/PycharmProjects/Auto_InterFace_GUI/venv/lib/python3.6/site-packages/django/core/handlers/base.py", line 115, in _get_response
    response = self.process_exception_by_middleware(e, request)
  File "/home/ma/PycharmProjects/Auto_InterFace_GUI/venv/lib/python3.6/site-packages/django/core/handlers/base.py", line 113, in _get_response
    response = wrapped_callback(request, *callback_args, **callback_kwargs)
  File "/home/ma/PycharmProjects/Auto_InterFace_GUI/upload_case/views.py", line 33, in index
    file_down = file_down(report_path)
TypeError: 'str' object is not callable
2019-09-17 13:55:41,591 [INFO] [/home/ma/PycharmProjects/Auto_InterFace_GUI/venv/lib/python3.6/site-packages/django/utils/autoreload.py] [trigger_reload ][django.utils.autoreload:217]- /home/ma/PycharmProjects/Auto_InterFace_GUI/upload_case/views.py changed, reloading.
2019-09-17 14:35:33,449 [INFO] [/home/ma/PycharmProjects/Auto_InterFace_GUI/venv/lib/python3.6/site-packages/django/utils/autoreload.py] [trigger_reload ][django.utils.autoreload:217]- /home/ma/PycharmProjects/Auto_InterFace_GUI/upload_case/case_test_common.py changed, reloading.
2019-09-17 14:55:15,551 [ERROR] [/home/ma/PycharmProjects/Auto_InterFace_GUI/venv/lib/python3.6/site-packages/django/utils/log.py] [log_response ][django.request:228]- Internal Server Error: /index/
Traceback (most recent call last):
  File "/home/ma/PycharmProjects/Auto_InterFace_GUI/venv/lib/python3.6/site-packages/django/core/handlers/exception.py", line 34, in inner
    response = get_response(request)
  File "/home/ma/PycharmProjects/Auto_InterFace_GUI/venv/lib/python3.6/site-packages/django/core/handlers/base.py", line 115, in _get_response
    response = self.process_exception_by_middleware(e, request)
  File "/home/ma/PycharmProjects/Auto_InterFace_GUI/venv/lib/python3.6/site-packages/django/core/handlers/base.py", line 113, in _get_response
    response = wrapped_callback(request, *callback_args, **callback_kwargs)
  File "/home/ma/PycharmProjects/Auto_InterFace_GUI/upload_case/views.py", line 36, in index
    pro_rep_all_path = get_all_path(show_all_path)
TypeError: get_all_path() missing 1 required positional argument: 'root_path'
2019-09-17 15:08:29,820 [INFO] [/home/ma/PycharmProjects/Auto_InterFace_GUI/venv/lib/python3.6/site-packages/django/utils/autoreload.py] [trigger_reload ][django.utils.autoreload:217]- /home/ma/PycharmProjects/Auto_InterFace_GUI/upload_case/views.py changed, reloading.
2019-09-17 15:34:02,393 [WARNING] [/home/ma/PycharmProjects/Auto_InterFace_GUI/venv/lib/python3.6/site-packages/django/utils/log.py] [log_response ][django.request:228]- Not Found: /favicon.ico
2019-09-17 15:34:23,605 [INFO] [/home/ma/PycharmProjects/Auto_InterFace_GUI/venv/lib/python3.6/site-packages/django/utils/autoreload.py] [trigger_reload ][django.utils.autoreload:217]- /home/ma/PycharmProjects/Auto_InterFace_GUI/upload_case/views.py changed, reloading.
2019-09-17 15:40:13,779 [INFO] [/home/ma/PycharmProjects/Auto_InterFace_GUI/venv/lib/python3.6/site-packages/django/utils/autoreload.py] [trigger_reload ][django.utils.autoreload:217]- /home/ma/PycharmProjects/Auto_InterFace_GUI/upload_case/views.py changed, reloading.
2019-09-17 15:42:08,882 [INFO] [/home/ma/PycharmProjects/Auto_InterFace_GUI/venv/lib/python3.6/site-packages/django/utils/autoreload.py] [trigger_reload ][django.utils.autoreload:217]- /home/ma/PycharmProjects/Auto_InterFace_GUI/upload_case/views.py changed, reloading.
2019-09-17 15:44:37,264 [INFO] [/home/ma/PycharmProjects/Auto_InterFace_GUI/venv/lib/python3.6/site-packages/django/utils/autoreload.py] [trigger_reload ][django.utils.autoreload:217]- /home/ma/PycharmProjects/Auto_InterFace_GUI/upload_case/views.py changed, reloading.
2019-09-17 15:59:31,729 [INFO] [/home/ma/PycharmProjects/Auto_InterFace_GUI/venv/lib/python3.6/site-packages/django/utils/autoreload.py] [trigger_reload ][django.utils.autoreload:217]- /home/ma/PycharmProjects/Auto_InterFace_GUI/upload_case/views.py changed, reloading.
2019-09-17 16:23:13,585 [INFO] [/home/ma/PycharmProjects/Auto_InterFace_GUI/venv/lib/python3.6/site-packages/django/utils/autoreload.py] [trigger_reload ][django.utils.autoreload:217]- /home/ma/PycharmProjects/Auto_InterFace_GUI/upload_case/views.py changed, reloading.
2019-09-17 16:25:15,034 [INFO] [/home/ma/PycharmProjects/Auto_InterFace_GUI/venv/lib/python3.6/site-packages/django/utils/autoreload.py] [trigger_reload ][django.utils.autoreload:217]- /home/ma/PycharmProjects/Auto_InterFace_GUI/upload_case/views.py changed, reloading.
