2019-09-18 09:49:33,927 [WARNING] [/home/ma/PycharmProjects/Auto_InterFace_GUI/venv/lib/python3.6/site-packages/django/utils/log.py] [log_response ][django.request:228]- Not Found: /home/ma/PycharmProjects/Auto_InterFace_GUI/InterfaceTest/static/project_tree/test2/report/20190918/manage20190918094925.html
2019-09-18 09:50:07,700 [ERROR] [/home/ma/PycharmProjects/Auto_InterFace_GUI/venv/lib/python3.6/site-packages/django/utils/log.py] [log_response ][django.request:228]- Internal Server Error: /getallpath
Traceback (most recent call last):
  File "/home/ma/PycharmProjects/Auto_InterFace_GUI/venv/lib/python3.6/site-packages/django/core/handlers/exception.py", line 34, in inner
    response = get_response(request)
  File "/home/ma/PycharmProjects/Auto_InterFace_GUI/venv/lib/python3.6/site-packages/django/core/handlers/base.py", line 115, in _get_response
    response = self.process_exception_by_middleware(e, request)
  File "/home/ma/PycharmProjects/Auto_InterFace_GUI/venv/lib/python3.6/site-packages/django/core/handlers/base.py", line 113, in _get_response
    response = wrapped_callback(request, *callback_args, **callback_kwargs)
  File "/home/ma/PycharmProjects/Auto_InterFace_GUI/upload_case/views.py", line 133, in get_all_path
    dir_or_files = os.listdir(root_path)
FileNotFoundError: [Errno 2] No such file or directory: ''
2019-09-18 09:50:38,731 [ERROR] [/home/ma/PycharmProjects/Auto_InterFace_GUI/venv/lib/python3.6/site-packages/django/utils/log.py] [log_response ][django.request:228]- Internal Server Error: /getallpath
Traceback (most recent call last):
  File "/home/ma/PycharmProjects/Auto_InterFace_GUI/venv/lib/python3.6/site-packages/django/core/handlers/exception.py", line 34, in inner
    response = get_response(request)
  File "/home/ma/PycharmProjects/Auto_InterFace_GUI/venv/lib/python3.6/site-packages/django/core/handlers/base.py", line 115, in _get_response
    response = self.process_exception_by_middleware(e, request)
  File "/home/ma/PycharmProjects/Auto_InterFace_GUI/venv/lib/python3.6/site-packages/django/core/handlers/base.py", line 113, in _get_response
    response = wrapped_callback(request, *callback_args, **callback_kwargs)
  File "/home/ma/PycharmProjects/Auto_InterFace_GUI/upload_case/views.py", line 133, in get_all_path
    dir_or_files = os.listdir(root_path)
FileNotFoundError: [Errno 2] No such file or directory: ''
2019-09-18 09:50:50,404 [ERROR] [/home/ma/PycharmProjects/Auto_InterFace_GUI/venv/lib/python3.6/site-packages/django/utils/log.py] [log_response ][django.request:228]- Internal Server Error: /getallpath
Traceback (most recent call last):
  File "/home/ma/PycharmProjects/Auto_InterFace_GUI/venv/lib/python3.6/site-packages/django/core/handlers/exception.py", line 34, in inner
    response = get_response(request)
  File "/home/ma/PycharmProjects/Auto_InterFace_GUI/venv/lib/python3.6/site-packages/django/core/handlers/base.py", line 115, in _get_response
    response = self.process_exception_by_middleware(e, request)
  File "/home/ma/PycharmProjects/Auto_InterFace_GUI/venv/lib/python3.6/site-packages/django/core/handlers/base.py", line 113, in _get_response
    response = wrapped_callback(request, *callback_args, **callback_kwargs)
  File "/home/ma/PycharmProjects/Auto_InterFace_GUI/upload_case/views.py", line 133, in get_all_path
    dir_or_files = os.listdir(root_path)
FileNotFoundError: [Errno 2] No such file or directory: ''
2019-09-18 10:22:38,282 [WARNING] [/home/ma/PycharmProjects/Auto_InterFace_GUI/venv/lib/python3.6/site-packages/django/utils/log.py] [log_response ][django.request:228]- Not Found: /home/ma/PycharmProjects/Auto_InterFace_GUI/InterfaceTest/static/project_tree/test2/report/20190918/manage20190918102224.html
2019-09-18 10:23:38,917 [ERROR] [/home/ma/PycharmProjects/Auto_InterFace_GUI/InterfaceTest/python_excel/get_data/param_global.py] [deal_param_name_tuple ][__file__:59]- 处理接口请求参数名出现异常，异常原因：list index out of range
2019-09-18 10:23:39,103 [ERROR] [/home/ma/PycharmProjects/Auto_InterFace_GUI/InterfaceTest/python_excel/get_data/param_global.py] [deal_param_name_tuple ][__file__:59]- 处理接口请求参数名出现异常，异常原因：list index out of range
2019-09-18 10:23:39,104 [ERROR] [/home/ma/PycharmProjects/Auto_InterFace_GUI/InterfaceTest/python_excel/get_data/param_global.py] [deal_param_name_tuple ][__file__:59]- 处理接口请求参数名出现异常，异常原因：list index out of range
2019-09-18 10:24:51,308 [WARNING] [/home/ma/PycharmProjects/Auto_InterFace_GUI/venv/lib/python3.6/site-packages/django/utils/log.py] [log_response ][django.request:228]- Not Found: /home/ma/PycharmProjects/Auto_InterFace_GUI/InterfaceTest/static/project_tree/TSA-IPPS-QZ/report/20190918/manage20190918102350.html
2019-09-18 10:26:25,632 [ERROR] [/home/ma/PycharmProjects/Auto_InterFace_GUI/InterfaceTest/python_excel/utils/operation_json.py] [read_data ][/home/ma/PycharmProjects/Auto_InterFace_GUI/InterfaceTest/python_excel/utils/operation_json.py:25]- 操作JSON类读取数据异常，异常原因：Extra data: line 5 column 2 (char 389)
2019-09-18 10:26:25,632 [ERROR] [/home/ma/PycharmProjects/Auto_InterFace_GUI/InterfaceTest/python_excel/utils/operation_json.py] [read_data ][/home/ma/PycharmProjects/Auto_InterFace_GUI/InterfaceTest/python_excel/utils/operation_json.py:25]- 操作JSON类读取数据异常，异常原因：Extra data: line 5 column 2 (char 389)
2019-09-18 10:26:25,632 [ERROR] [/home/ma/PycharmProjects/Auto_InterFace_GUI/InterfaceTest/python_excel/utils/operation_json.py] [get_data_for_key ][/home/ma/PycharmProjects/Auto_InterFace_GUI/InterfaceTest/python_excel/utils/operation_json.py:39]- 操作JSON类根据key获取value异常，异常原因：'NoneType' object is not subscriptable
2019-09-18 10:26:25,633 [ERROR] [/home/ma/PycharmProjects/Auto_InterFace_GUI/InterfaceTest/python_excel/utils/operation_json.py] [read_data ][/home/ma/PycharmProjects/Auto_InterFace_GUI/InterfaceTest/python_excel/utils/operation_json.py:25]- 操作JSON类读取数据异常，异常原因：Extra data: line 5 column 2 (char 389)
2019-09-18 10:26:25,633 [ERROR] [/home/ma/PycharmProjects/Auto_InterFace_GUI/InterfaceTest/python_excel/utils/operation_json.py] [get_data_for_key ][/home/ma/PycharmProjects/Auto_InterFace_GUI/InterfaceTest/python_excel/utils/operation_json.py:39]- 操作JSON类根据key获取value异常，异常原因：'NoneType' object is not subscriptable
2019-09-18 10:26:25,633 [ERROR] [/home/ma/PycharmProjects/Auto_InterFace_GUI/InterfaceTest/python_excel/utils/operation_json.py] [read_data ][/home/ma/PycharmProjects/Auto_InterFace_GUI/InterfaceTest/python_excel/utils/operation_json.py:25]- 操作JSON类读取数据异常，异常原因：Extra data: line 5 column 2 (char 389)
2019-09-18 10:26:25,633 [ERROR] [/home/ma/PycharmProjects/Auto_InterFace_GUI/InterfaceTest/python_excel/utils/operation_json.py] [get_data_for_key ][/home/ma/PycharmProjects/Auto_InterFace_GUI/InterfaceTest/python_excel/utils/operation_json.py:39]- 操作JSON类根据key获取value异常，异常原因：'NoneType' object is not subscriptable
2019-09-18 10:26:25,633 [ERROR] [/home/ma/PycharmProjects/Auto_InterFace_GUI/InterfaceTest/python_excel/utils/operation_cfg.py] [read_cfg ][__file__:31]- 读取cfg配置文件内容异常，异常原因：'NoneType' object is not iterable
2019-09-18 10:26:25,633 [ERROR] [/home/ma/PycharmProjects/Auto_InterFace_GUI/InterfaceTest/python_excel/utils/operation_cfg.py] [get_section_option_list ][__file__:82]- 读取配置文件指定段section下所有option列表出现异常，异常原因：No section: 'my_case_file'
2019-09-18 10:26:34,571 [ERROR] [/home/ma/PycharmProjects/Auto_InterFace_GUI/venv/lib/python3.6/site-packages/django/utils/log.py] [log_response ][django.request:228]- Internal Server Error: /
Traceback (most recent call last):
  File "/home/ma/PycharmProjects/Auto_InterFace_GUI/venv/lib/python3.6/site-packages/django/core/handlers/exception.py", line 34, in inner
    response = get_response(request)
  File "/home/ma/PycharmProjects/Auto_InterFace_GUI/venv/lib/python3.6/site-packages/django/core/handlers/base.py", line 115, in _get_response
    response = self.process_exception_by_middleware(e, request)
  File "/home/ma/PycharmProjects/Auto_InterFace_GUI/venv/lib/python3.6/site-packages/django/core/handlers/base.py", line 113, in _get_response
    response = wrapped_callback(request, *callback_args, **callback_kwargs)
  File "/home/ma/PycharmProjects/Auto_InterFace_GUI/upload_case/views.py", line 32, in index
    from upload_case import case_test_common
  File "/home/ma/PycharmProjects/Auto_InterFace_GUI/upload_case/case_test_common.py", line 37, in <module>
    filename = option_dict["case_filepath"]
KeyError: 'case_filepath'
2019-09-18 13:33:06,780 [ERROR] [/home/ma/PycharmProjects/Auto_InterFace_GUI/InterfaceTest/python_excel/utils/operation_json.py] [read_data ][/home/ma/PycharmProjects/Auto_InterFace_GUI/InterfaceTest/python_excel/utils/operation_json.py:25]- 操作JSON类读取数据异常，异常原因：Extra data: line 5 column 2 (char 389)
2019-09-18 13:33:06,782 [ERROR] [/home/ma/PycharmProjects/Auto_InterFace_GUI/InterfaceTest/python_excel/utils/operation_json.py] [read_data ][/home/ma/PycharmProjects/Auto_InterFace_GUI/InterfaceTest/python_excel/utils/operation_json.py:25]- 操作JSON类读取数据异常，异常原因：Extra data: line 5 column 2 (char 389)
2019-09-18 13:33:06,782 [ERROR] [/home/ma/PycharmProjects/Auto_InterFace_GUI/InterfaceTest/python_excel/utils/operation_json.py] [get_data_for_key ][/home/ma/PycharmProjects/Auto_InterFace_GUI/InterfaceTest/python_excel/utils/operation_json.py:39]- 操作JSON类根据key获取value异常，异常原因：'NoneType' object is not subscriptable
2019-09-18 13:33:06,783 [ERROR] [/home/ma/PycharmProjects/Auto_InterFace_GUI/InterfaceTest/python_excel/utils/operation_json.py] [read_data ][/home/ma/PycharmProjects/Auto_InterFace_GUI/InterfaceTest/python_excel/utils/operation_json.py:25]- 操作JSON类读取数据异常，异常原因：Extra data: line 5 column 2 (char 389)
2019-09-18 13:33:06,784 [ERROR] [/home/ma/PycharmProjects/Auto_InterFace_GUI/InterfaceTest/python_excel/utils/operation_json.py] [get_data_for_key ][/home/ma/PycharmProjects/Auto_InterFace_GUI/InterfaceTest/python_excel/utils/operation_json.py:39]- 操作JSON类根据key获取value异常，异常原因：'NoneType' object is not subscriptable
2019-09-18 13:33:06,785 [ERROR] [/home/ma/PycharmProjects/Auto_InterFace_GUI/InterfaceTest/python_excel/utils/operation_json.py] [read_data ][/home/ma/PycharmProjects/Auto_InterFace_GUI/InterfaceTest/python_excel/utils/operation_json.py:25]- 操作JSON类读取数据异常，异常原因：Extra data: line 5 column 2 (char 389)
2019-09-18 13:33:06,785 [ERROR] [/home/ma/PycharmProjects/Auto_InterFace_GUI/InterfaceTest/python_excel/utils/operation_json.py] [get_data_for_key ][/home/ma/PycharmProjects/Auto_InterFace_GUI/InterfaceTest/python_excel/utils/operation_json.py:39]- 操作JSON类根据key获取value异常，异常原因：'NoneType' object is not subscriptable
2019-09-18 13:33:06,786 [ERROR] [/home/ma/PycharmProjects/Auto_InterFace_GUI/InterfaceTest/python_excel/utils/operation_cfg.py] [read_cfg ][__file__:31]- 读取cfg配置文件内容异常，异常原因：'NoneType' object is not iterable
2019-09-18 13:33:06,787 [ERROR] [/home/ma/PycharmProjects/Auto_InterFace_GUI/InterfaceTest/python_excel/utils/operation_cfg.py] [get_section_option_list ][__file__:82]- 读取配置文件指定段section下所有option列表出现异常，异常原因：No section: 'my_case_file'
2019-09-18 13:33:51,278 [ERROR] [/home/ma/PycharmProjects/Auto_InterFace_GUI/InterfaceTest/python_excel/utils/operation_json.py] [read_data ][/home/ma/PycharmProjects/Auto_InterFace_GUI/InterfaceTest/python_excel/utils/operation_json.py:25]- 操作JSON类读取数据异常，异常原因：Extra data: line 5 column 2 (char 389)
2019-09-18 13:33:51,278 [ERROR] [/home/ma/PycharmProjects/Auto_InterFace_GUI/InterfaceTest/python_excel/utils/operation_json.py] [read_data ][/home/ma/PycharmProjects/Auto_InterFace_GUI/InterfaceTest/python_excel/utils/operation_json.py:25]- 操作JSON类读取数据异常，异常原因：Extra data: line 5 column 2 (char 389)
2019-09-18 13:33:51,279 [ERROR] [/home/ma/PycharmProjects/Auto_InterFace_GUI/InterfaceTest/python_excel/utils/operation_json.py] [get_data_for_key ][/home/ma/PycharmProjects/Auto_InterFace_GUI/InterfaceTest/python_excel/utils/operation_json.py:39]- 操作JSON类根据key获取value异常，异常原因：'NoneType' object is not subscriptable
2019-09-18 13:33:51,279 [ERROR] [/home/ma/PycharmProjects/Auto_InterFace_GUI/InterfaceTest/python_excel/utils/operation_json.py] [read_data ][/home/ma/PycharmProjects/Auto_InterFace_GUI/InterfaceTest/python_excel/utils/operation_json.py:25]- 操作JSON类读取数据异常，异常原因：Extra data: line 5 column 2 (char 389)
2019-09-18 13:33:51,279 [ERROR] [/home/ma/PycharmProjects/Auto_InterFace_GUI/InterfaceTest/python_excel/utils/operation_json.py] [get_data_for_key ][/home/ma/PycharmProjects/Auto_InterFace_GUI/InterfaceTest/python_excel/utils/operation_json.py:39]- 操作JSON类根据key获取value异常，异常原因：'NoneType' object is not subscriptable
2019-09-18 13:33:51,279 [ERROR] [/home/ma/PycharmProjects/Auto_InterFace_GUI/InterfaceTest/python_excel/utils/operation_json.py] [read_data ][/home/ma/PycharmProjects/Auto_InterFace_GUI/InterfaceTest/python_excel/utils/operation_json.py:25]- 操作JSON类读取数据异常，异常原因：Extra data: line 5 column 2 (char 389)
2019-09-18 13:33:51,280 [ERROR] [/home/ma/PycharmProjects/Auto_InterFace_GUI/InterfaceTest/python_excel/utils/operation_json.py] [get_data_for_key ][/home/ma/PycharmProjects/Auto_InterFace_GUI/InterfaceTest/python_excel/utils/operation_json.py:39]- 操作JSON类根据key获取value异常，异常原因：'NoneType' object is not subscriptable
2019-09-18 13:33:51,280 [ERROR] [/home/ma/PycharmProjects/Auto_InterFace_GUI/InterfaceTest/python_excel/utils/operation_cfg.py] [read_cfg ][__file__:31]- 读取cfg配置文件内容异常，异常原因：'NoneType' object is not iterable
2019-09-18 13:33:51,300 [ERROR] [/home/ma/PycharmProjects/Auto_InterFace_GUI/InterfaceTest/python_excel/utils/operation_json.py] [read_data ][/home/ma/PycharmProjects/Auto_InterFace_GUI/InterfaceTest/python_excel/utils/operation_json.py:25]- 操作JSON类读取数据异常，异常原因：Extra data: line 5 column 2 (char 389)
2019-09-18 13:33:51,300 [ERROR] [/home/ma/PycharmProjects/Auto_InterFace_GUI/InterfaceTest/python_excel/utils/operation_json.py] [get_data_for_key ][/home/ma/PycharmProjects/Auto_InterFace_GUI/InterfaceTest/python_excel/utils/operation_json.py:39]- 操作JSON类根据key获取value异常，异常原因：'NoneType' object is not subscriptable
2019-09-18 13:33:51,300 [ERROR] [/home/ma/PycharmProjects/Auto_InterFace_GUI/InterfaceTest/python_excel/utils/operation_json.py] [read_data ][/home/ma/PycharmProjects/Auto_InterFace_GUI/InterfaceTest/python_excel/utils/operation_json.py:25]- 操作JSON类读取数据异常，异常原因：Extra data: line 5 column 2 (char 389)
2019-09-18 13:33:51,301 [ERROR] [/home/ma/PycharmProjects/Auto_InterFace_GUI/InterfaceTest/python_excel/utils/operation_json.py] [get_data_for_key ][/home/ma/PycharmProjects/Auto_InterFace_GUI/InterfaceTest/python_excel/utils/operation_json.py:39]- 操作JSON类根据key获取value异常，异常原因：'NoneType' object is not subscriptable
2019-09-18 13:33:51,317 [ERROR] [/home/ma/PycharmProjects/Auto_InterFace_GUI/InterfaceTest/python_excel/utils/operation_json.py] [read_data ][/home/ma/PycharmProjects/Auto_InterFace_GUI/InterfaceTest/python_excel/utils/operation_json.py:25]- 操作JSON类读取数据异常，异常原因：Extra data: line 5 column 2 (char 389)
2019-09-18 13:33:51,318 [ERROR] [/home/ma/PycharmProjects/Auto_InterFace_GUI/InterfaceTest/python_excel/utils/operation_json.py] [get_data_for_key ][/home/ma/PycharmProjects/Auto_InterFace_GUI/InterfaceTest/python_excel/utils/operation_json.py:39]- 操作JSON类根据key获取value异常，异常原因：'NoneType' object is not subscriptable
2019-09-18 13:33:51,319 [ERROR] [/home/ma/PycharmProjects/Auto_InterFace_GUI/InterfaceTest/python_excel/utils/operation_json.py] [read_data ][/home/ma/PycharmProjects/Auto_InterFace_GUI/InterfaceTest/python_excel/utils/operation_json.py:25]- 操作JSON类读取数据异常，异常原因：Extra data: line 5 column 2 (char 389)
2019-09-18 13:33:51,319 [ERROR] [/home/ma/PycharmProjects/Auto_InterFace_GUI/InterfaceTest/python_excel/utils/operation_json.py] [get_data_for_key ][/home/ma/PycharmProjects/Auto_InterFace_GUI/InterfaceTest/python_excel/utils/operation_json.py:39]- 操作JSON类根据key获取value异常，异常原因：'NoneType' object is not subscriptable
2019-09-18 13:40:21,221 [ERROR] [/home/ma/PycharmProjects/Auto_InterFace_GUI/InterfaceTest/python_excel/utils/operation_json.py] [read_data ][/home/ma/PycharmProjects/Auto_InterFace_GUI/InterfaceTest/python_excel/utils/operation_json.py:25]- 操作JSON类读取数据异常，异常原因：Extra data: line 5 column 2 (char 389)
2019-09-18 13:40:21,221 [ERROR] [/home/ma/PycharmProjects/Auto_InterFace_GUI/InterfaceTest/python_excel/utils/operation_json.py] [read_data ][/home/ma/PycharmProjects/Auto_InterFace_GUI/InterfaceTest/python_excel/utils/operation_json.py:25]- 操作JSON类读取数据异常，异常原因：Extra data: line 5 column 2 (char 389)
2019-09-18 13:40:21,221 [ERROR] [/home/ma/PycharmProjects/Auto_InterFace_GUI/InterfaceTest/python_excel/utils/operation_json.py] [get_data_for_key ][/home/ma/PycharmProjects/Auto_InterFace_GUI/InterfaceTest/python_excel/utils/operation_json.py:39]- 操作JSON类根据key获取value异常，异常原因：'NoneType' object is not subscriptable
2019-09-18 13:40:21,221 [ERROR] [/home/ma/PycharmProjects/Auto_InterFace_GUI/InterfaceTest/python_excel/utils/operation_json.py] [read_data ][/home/ma/PycharmProjects/Auto_InterFace_GUI/InterfaceTest/python_excel/utils/operation_json.py:25]- 操作JSON类读取数据异常，异常原因：Extra data: line 5 column 2 (char 389)
2019-09-18 13:40:21,222 [ERROR] [/home/ma/PycharmProjects/Auto_InterFace_GUI/InterfaceTest/python_excel/utils/operation_json.py] [get_data_for_key ][/home/ma/PycharmProjects/Auto_InterFace_GUI/InterfaceTest/python_excel/utils/operation_json.py:39]- 操作JSON类根据key获取value异常，异常原因：'NoneType' object is not subscriptable
2019-09-18 13:40:21,222 [ERROR] [/home/ma/PycharmProjects/Auto_InterFace_GUI/InterfaceTest/python_excel/utils/operation_json.py] [read_data ][/home/ma/PycharmProjects/Auto_InterFace_GUI/InterfaceTest/python_excel/utils/operation_json.py:25]- 操作JSON类读取数据异常，异常原因：Extra data: line 5 column 2 (char 389)
2019-09-18 13:40:21,222 [ERROR] [/home/ma/PycharmProjects/Auto_InterFace_GUI/InterfaceTest/python_excel/utils/operation_json.py] [get_data_for_key ][/home/ma/PycharmProjects/Auto_InterFace_GUI/InterfaceTest/python_excel/utils/operation_json.py:39]- 操作JSON类根据key获取value异常，异常原因：'NoneType' object is not subscriptable
2019-09-18 13:40:21,222 [ERROR] [/home/ma/PycharmProjects/Auto_InterFace_GUI/InterfaceTest/python_excel/utils/operation_cfg.py] [read_cfg ][__file__:31]- 读取cfg配置文件内容异常，异常原因：'NoneType' object is not iterable
2019-09-18 13:40:21,249 [ERROR] [/home/ma/PycharmProjects/Auto_InterFace_GUI/InterfaceTest/python_excel/utils/operation_json.py] [read_data ][/home/ma/PycharmProjects/Auto_InterFace_GUI/InterfaceTest/python_excel/utils/operation_json.py:25]- 操作JSON类读取数据异常，异常原因：Extra data: line 5 column 2 (char 389)
2019-09-18 13:40:21,249 [ERROR] [/home/ma/PycharmProjects/Auto_InterFace_GUI/InterfaceTest/python_excel/utils/operation_json.py] [get_data_for_key ][/home/ma/PycharmProjects/Auto_InterFace_GUI/InterfaceTest/python_excel/utils/operation_json.py:39]- 操作JSON类根据key获取value异常，异常原因：'NoneType' object is not subscriptable
2019-09-18 13:40:21,249 [ERROR] [/home/ma/PycharmProjects/Auto_InterFace_GUI/InterfaceTest/python_excel/utils/operation_json.py] [read_data ][/home/ma/PycharmProjects/Auto_InterFace_GUI/InterfaceTest/python_excel/utils/operation_json.py:25]- 操作JSON类读取数据异常，异常原因：Extra data: line 5 column 2 (char 389)
2019-09-18 13:40:21,249 [ERROR] [/home/ma/PycharmProjects/Auto_InterFace_GUI/InterfaceTest/python_excel/utils/operation_json.py] [get_data_for_key ][/home/ma/PycharmProjects/Auto_InterFace_GUI/InterfaceTest/python_excel/utils/operation_json.py:39]- 操作JSON类根据key获取value异常，异常原因：'NoneType' object is not subscriptable
2019-09-18 13:40:21,275 [ERROR] [/home/ma/PycharmProjects/Auto_InterFace_GUI/InterfaceTest/python_excel/utils/operation_json.py] [read_data ][/home/ma/PycharmProjects/Auto_InterFace_GUI/InterfaceTest/python_excel/utils/operation_json.py:25]- 操作JSON类读取数据异常，异常原因：Extra data: line 5 column 2 (char 389)
2019-09-18 13:40:21,275 [ERROR] [/home/ma/PycharmProjects/Auto_InterFace_GUI/InterfaceTest/python_excel/utils/operation_json.py] [get_data_for_key ][/home/ma/PycharmProjects/Auto_InterFace_GUI/InterfaceTest/python_excel/utils/operation_json.py:39]- 操作JSON类根据key获取value异常，异常原因：'NoneType' object is not subscriptable
2019-09-18 13:40:21,276 [ERROR] [/home/ma/PycharmProjects/Auto_InterFace_GUI/InterfaceTest/python_excel/utils/operation_json.py] [read_data ][/home/ma/PycharmProjects/Auto_InterFace_GUI/InterfaceTest/python_excel/utils/operation_json.py:25]- 操作JSON类读取数据异常，异常原因：Extra data: line 5 column 2 (char 389)
2019-09-18 13:40:21,276 [ERROR] [/home/ma/PycharmProjects/Auto_InterFace_GUI/InterfaceTest/python_excel/utils/operation_json.py] [get_data_for_key ][/home/ma/PycharmProjects/Auto_InterFace_GUI/InterfaceTest/python_excel/utils/operation_json.py:39]- 操作JSON类根据key获取value异常，异常原因：'NoneType' object is not subscriptable
2019-09-18 13:40:34,508 [ERROR] [/home/ma/PycharmProjects/Auto_InterFace_GUI/InterfaceTest/python_excel/utils/operation_cfg.py] [get_section_option_list ][__file__:82]- 读取配置文件指定段section下所有option列表出现异常，异常原因：No section: 'my_case_file'
2019-09-18 13:40:34,578 [ERROR] [/home/ma/PycharmProjects/Auto_InterFace_GUI/InterfaceTest/python_excel/utils/operation_json.py] [read_data ][/home/ma/PycharmProjects/Auto_InterFace_GUI/InterfaceTest/python_excel/utils/operation_json.py:25]- 操作JSON类读取数据异常，异常原因：Extra data: line 5 column 2 (char 389)
2019-09-18 13:40:34,579 [ERROR] [/home/ma/PycharmProjects/Auto_InterFace_GUI/InterfaceTest/python_excel/utils/operation_json.py] [get_data_for_key ][/home/ma/PycharmProjects/Auto_InterFace_GUI/InterfaceTest/python_excel/utils/operation_json.py:39]- 操作JSON类根据key获取value异常，异常原因：'NoneType' object is not subscriptable
2019-09-18 13:40:34,580 [ERROR] [/home/ma/PycharmProjects/Auto_InterFace_GUI/InterfaceTest/python_excel/utils/operation_json.py] [read_data ][/home/ma/PycharmProjects/Auto_InterFace_GUI/InterfaceTest/python_excel/utils/operation_json.py:25]- 操作JSON类读取数据异常，异常原因：Extra data: line 5 column 2 (char 389)
2019-09-18 13:40:34,580 [ERROR] [/home/ma/PycharmProjects/Auto_InterFace_GUI/InterfaceTest/python_excel/utils/operation_json.py] [get_data_for_key ][/home/ma/PycharmProjects/Auto_InterFace_GUI/InterfaceTest/python_excel/utils/operation_json.py:39]- 操作JSON类根据key获取value异常，异常原因：'NoneType' object is not subscriptable
2019-09-18 13:40:34,602 [ERROR] [/home/ma/PycharmProjects/Auto_InterFace_GUI/InterfaceTest/python_excel/utils/operation_json.py] [read_data ][/home/ma/PycharmProjects/Auto_InterFace_GUI/InterfaceTest/python_excel/utils/operation_json.py:25]- 操作JSON类读取数据异常，异常原因：Extra data: line 5 column 2 (char 389)
2019-09-18 13:40:34,602 [ERROR] [/home/ma/PycharmProjects/Auto_InterFace_GUI/InterfaceTest/python_excel/utils/operation_json.py] [get_data_for_key ][/home/ma/PycharmProjects/Auto_InterFace_GUI/InterfaceTest/python_excel/utils/operation_json.py:39]- 操作JSON类根据key获取value异常，异常原因：'NoneType' object is not subscriptable
2019-09-18 13:40:34,603 [ERROR] [/home/ma/PycharmProjects/Auto_InterFace_GUI/InterfaceTest/python_excel/utils/operation_json.py] [read_data ][/home/ma/PycharmProjects/Auto_InterFace_GUI/InterfaceTest/python_excel/utils/operation_json.py:25]- 操作JSON类读取数据异常，异常原因：Extra data: line 5 column 2 (char 389)
2019-09-18 13:40:34,603 [ERROR] [/home/ma/PycharmProjects/Auto_InterFace_GUI/InterfaceTest/python_excel/utils/operation_json.py] [get_data_for_key ][/home/ma/PycharmProjects/Auto_InterFace_GUI/InterfaceTest/python_excel/utils/operation_json.py:39]- 操作JSON类根据key获取value异常，异常原因：'NoneType' object is not subscriptable
2019-09-18 13:40:37,977 [ERROR] [/home/ma/PycharmProjects/Auto_InterFace_GUI/InterfaceTest/python_excel/utils/operation_json.py] [read_data ][/home/ma/PycharmProjects/Auto_InterFace_GUI/InterfaceTest/python_excel/utils/operation_json.py:25]- 操作JSON类读取数据异常，异常原因：Extra data: line 5 column 2 (char 389)
2019-09-18 13:40:37,977 [ERROR] [/home/ma/PycharmProjects/Auto_InterFace_GUI/InterfaceTest/python_excel/utils/operation_json.py] [get_data_for_key ][/home/ma/PycharmProjects/Auto_InterFace_GUI/InterfaceTest/python_excel/utils/operation_json.py:39]- 操作JSON类根据key获取value异常，异常原因：'NoneType' object is not subscriptable
2019-09-18 13:40:37,990 [ERROR] [/home/ma/PycharmProjects/Auto_InterFace_GUI/InterfaceTest/python_excel/utils/operation_json.py] [read_data ][/home/ma/PycharmProjects/Auto_InterFace_GUI/InterfaceTest/python_excel/utils/operation_json.py:25]- 操作JSON类读取数据异常，异常原因：Extra data: line 5 column 2 (char 389)
2019-09-18 13:40:37,991 [ERROR] [/home/ma/PycharmProjects/Auto_InterFace_GUI/InterfaceTest/python_excel/utils/operation_json.py] [get_data_for_key ][/home/ma/PycharmProjects/Auto_InterFace_GUI/InterfaceTest/python_excel/utils/operation_json.py:39]- 操作JSON类根据key获取value异常，异常原因：'NoneType' object is not subscriptable
2019-09-18 13:40:38,003 [ERROR] [/home/ma/PycharmProjects/Auto_InterFace_GUI/InterfaceTest/python_excel/utils/operation_json.py] [read_data ][/home/ma/PycharmProjects/Auto_InterFace_GUI/InterfaceTest/python_excel/utils/operation_json.py:25]- 操作JSON类读取数据异常，异常原因：Extra data: line 5 column 2 (char 389)
2019-09-18 13:40:38,003 [ERROR] [/home/ma/PycharmProjects/Auto_InterFace_GUI/InterfaceTest/python_excel/utils/operation_json.py] [get_data_for_key ][/home/ma/PycharmProjects/Auto_InterFace_GUI/InterfaceTest/python_excel/utils/operation_json.py:39]- 操作JSON类根据key获取value异常，异常原因：'NoneType' object is not subscriptable
2019-09-18 13:40:38,004 [ERROR] [/home/ma/PycharmProjects/Auto_InterFace_GUI/InterfaceTest/python_excel/utils/operation_json.py] [read_data ][/home/ma/PycharmProjects/Auto_InterFace_GUI/InterfaceTest/python_excel/utils/operation_json.py:25]- 操作JSON类读取数据异常，异常原因：Extra data: line 5 column 2 (char 389)
2019-09-18 13:40:38,004 [ERROR] [/home/ma/PycharmProjects/Auto_InterFace_GUI/InterfaceTest/python_excel/utils/operation_json.py] [get_data_for_key ][/home/ma/PycharmProjects/Auto_InterFace_GUI/InterfaceTest/python_excel/utils/operation_json.py:39]- 操作JSON类根据key获取value异常，异常原因：'NoneType' object is not subscriptable
2019-09-18 13:40:45,836 [ERROR] [/home/ma/PycharmProjects/Auto_InterFace_GUI/venv/lib/python3.6/site-packages/django/utils/log.py] [log_response ][django.request:228]- Internal Server Error: /
Traceback (most recent call last):
  File "/home/ma/PycharmProjects/Auto_InterFace_GUI/venv/lib/python3.6/site-packages/django/core/handlers/exception.py", line 34, in inner
    response = get_response(request)
  File "/home/ma/PycharmProjects/Auto_InterFace_GUI/venv/lib/python3.6/site-packages/django/core/handlers/base.py", line 115, in _get_response
    response = self.process_exception_by_middleware(e, request)
  File "/home/ma/PycharmProjects/Auto_InterFace_GUI/venv/lib/python3.6/site-packages/django/core/handlers/base.py", line 113, in _get_response
    response = wrapped_callback(request, *callback_args, **callback_kwargs)
  File "/home/ma/PycharmProjects/Auto_InterFace_GUI/upload_case/views.py", line 32, in index
    from upload_case import case_test_common
  File "/home/ma/PycharmProjects/Auto_InterFace_GUI/upload_case/case_test_common.py", line 37, in <module>
    filename = option_dict["case_filepath"]
KeyError: 'case_filepath'
2019-09-18 13:41:55,039 [ERROR] [/home/ma/PycharmProjects/Auto_InterFace_GUI/InterfaceTest/python_excel/get_data/param_global.py] [deal_param_name_tuple ][__file__:59]- 处理接口请求参数名出现异常，异常原因：list index out of range
2019-09-18 13:41:56,073 [ERROR] [/home/ma/PycharmProjects/Auto_InterFace_GUI/InterfaceTest/python_excel/get_data/param_global.py] [deal_param_name_tuple ][__file__:59]- 处理接口请求参数名出现异常，异常原因：list index out of range
2019-09-18 13:41:56,552 [ERROR] [/home/ma/PycharmProjects/Auto_InterFace_GUI/InterfaceTest/python_excel/get_data/param_global.py] [deal_param_name_tuple ][__file__:59]- 处理接口请求参数名出现异常，异常原因：list index out of range
2019-09-18 13:44:07,026 [INFO] [/home/ma/PycharmProjects/Auto_InterFace_GUI/venv/lib/python3.6/site-packages/django/utils/autoreload.py] [trigger_reload ][django.utils.autoreload:217]- /home/ma/PycharmProjects/Auto_InterFace_GUI/upload_case/views.py changed, reloading.
2019-09-18 13:44:54,752 [ERROR] [/home/ma/PycharmProjects/Auto_InterFace_GUI/InterfaceTest/python_excel/get_data/param_global.py] [deal_param_name_tuple ][__file__:59]- 处理接口请求参数名出现异常，异常原因：list index out of range
2019-09-18 13:44:55,739 [ERROR] [/home/ma/PycharmProjects/Auto_InterFace_GUI/InterfaceTest/python_excel/get_data/param_global.py] [deal_param_name_tuple ][__file__:59]- 处理接口请求参数名出现异常，异常原因：list index out of range
2019-09-18 13:44:56,224 [ERROR] [/home/ma/PycharmProjects/Auto_InterFace_GUI/InterfaceTest/python_excel/get_data/param_global.py] [deal_param_name_tuple ][__file__:59]- 处理接口请求参数名出现异常，异常原因：list index out of range
2019-09-18 13:47:56,660 [INFO] [/home/ma/PycharmProjects/Auto_InterFace_GUI/venv/lib/python3.6/site-packages/django/utils/autoreload.py] [trigger_reload ][django.utils.autoreload:217]- /home/ma/PycharmProjects/Auto_InterFace_GUI/InterfaceTest/python_excel/common/cmp_res_req.py changed, reloading.
2019-09-18 14:09:15,253 [ERROR] [/home/ma/PycharmProjects/Auto_InterFace_GUI/InterfaceTest/python_excel/get_data/param_global.py] [deal_param_name_tuple ][__file__:59]- 处理接口请求参数名出现异常，异常原因：list index out of range
2019-09-18 14:09:15,336 [ERROR] [/home/ma/PycharmProjects/Auto_InterFace_GUI/InterfaceTest/python_excel/get_data/param_global.py] [deal_param_name_tuple ][__file__:59]- 处理接口请求参数名出现异常，异常原因：list index out of range
2019-09-18 14:09:15,337 [ERROR] [/home/ma/PycharmProjects/Auto_InterFace_GUI/InterfaceTest/python_excel/get_data/param_global.py] [deal_param_name_tuple ][__file__:59]- 处理接口请求参数名出现异常，异常原因：list index out of range
2019-09-18 14:09:15,338 [ERROR] [/home/ma/PycharmProjects/Auto_InterFace_GUI/InterfaceTest/python_excel/get_data/param_global.py] [deal_param_name_tuple ][__file__:59]- 处理接口请求参数名出现异常，异常原因：list index out of range
2019-09-18 14:17:54,726 [INFO] [/home/ma/PycharmProjects/Auto_InterFace_GUI/venv/lib/python3.6/site-packages/django/utils/autoreload.py] [trigger_reload ][django.utils.autoreload:217]- /home/ma/PycharmProjects/Auto_InterFace_GUI/InterfaceTest/python_excel/utils/ElasticObj.py changed, reloading.
2019-09-18 14:28:09,801 [ERROR] [/home/ma/PycharmProjects/Auto_InterFace_GUI/InterfaceTest/python_excel/get_data/param_global.py] [deal_param_name_tuple ][__file__:59]- 处理接口请求参数名出现异常，异常原因：list index out of range
2019-09-18 14:28:09,965 [ERROR] [/home/ma/PycharmProjects/Auto_InterFace_GUI/InterfaceTest/python_excel/get_data/param_global.py] [deal_param_name_tuple ][__file__:59]- 处理接口请求参数名出现异常，异常原因：list index out of range
2019-09-18 14:28:09,966 [ERROR] [/home/ma/PycharmProjects/Auto_InterFace_GUI/InterfaceTest/python_excel/get_data/param_global.py] [deal_param_name_tuple ][__file__:59]- 处理接口请求参数名出现异常，异常原因：list index out of range
2019-09-18 14:28:14,989 [ERROR] [/home/ma/PycharmProjects/Auto_InterFace_GUI/InterfaceTest/python_excel/get_data/param_global.py] [deal_param_name_tuple ][__file__:59]- 处理接口请求参数名出现异常，异常原因：list index out of range
2019-09-18 14:33:33,321 [INFO] [/home/ma/PycharmProjects/Auto_InterFace_GUI/venv/lib/python3.6/site-packages/django/utils/autoreload.py] [trigger_reload ][django.utils.autoreload:217]- /home/ma/PycharmProjects/Auto_InterFace_GUI/upload_case/views.py changed, reloading.
2019-09-18 14:34:41,051 [ERROR] [/home/ma/PycharmProjects/Auto_InterFace_GUI/InterfaceTest/python_excel/get_data/param_global.py] [deal_param_name_tuple ][__file__:59]- 处理接口请求参数名出现异常，异常原因：list index out of range
2019-09-18 14:34:41,226 [ERROR] [/home/ma/PycharmProjects/Auto_InterFace_GUI/InterfaceTest/python_excel/get_data/param_global.py] [deal_param_name_tuple ][__file__:59]- 处理接口请求参数名出现异常，异常原因：list index out of range
2019-09-18 14:34:41,226 [ERROR] [/home/ma/PycharmProjects/Auto_InterFace_GUI/InterfaceTest/python_excel/get_data/param_global.py] [deal_param_name_tuple ][__file__:59]- 处理接口请求参数名出现异常，异常原因：list index out of range
2019-09-18 14:34:44,609 [ERROR] [/home/ma/PycharmProjects/Auto_InterFace_GUI/InterfaceTest/python_excel/get_data/param_global.py] [deal_param_name_tuple ][__file__:59]- 处理接口请求参数名出现异常，异常原因：list index out of range
2019-09-18 14:34:49,534 [INFO] [/home/ma/PycharmProjects/Auto_InterFace_GUI/venv/lib/python3.6/site-packages/elasticsearch/connection/base.py] [log_request_success ][elasticsearch:121]- GET http://39.107.66.190:9200/evidence/_search [status:200 request:0.051s]
2019-09-18 14:34:49,549 [ERROR] [/home/ma/PycharmProjects/Auto_InterFace_GUI/InterfaceTest/python_excel/common/cmp_res_req.py] [verify_database ][/home/ma/PycharmProjects/Auto_InterFace_GUI/InterfaceTest/python_excel/common/cmp_res_req.py:142]- 测试用例请求参数与存储结果对比出现异常，异常原因：'bool' object is not subscriptable
2019-09-18 14:34:49,550 [ERROR] [/home/ma/PycharmProjects/Auto_InterFace_GUI/InterfaceTest/python_excel/common/cmp_res_req.py] [verify_is_pass ][/home/ma/PycharmProjects/Auto_InterFace_GUI/InterfaceTest/python_excel/common/cmp_res_req.py:73]- 测试用例预期结果与实际结果对比方法出现异常，异常原因：local variable 'callbackurl_flag' referenced before assignment
2019-09-18 14:41:22,004 [INFO] [/home/ma/PycharmProjects/Auto_InterFace_GUI/venv/lib/python3.6/site-packages/django/utils/autoreload.py] [trigger_reload ][django.utils.autoreload:217]- /home/ma/PycharmProjects/Auto_InterFace_GUI/InterfaceTest/python_excel/utils/ElasticObj.py changed, reloading.
2019-09-18 15:10:35,712 [ERROR] [/home/ma/PycharmProjects/Auto_InterFace_GUI/InterfaceTest/python_excel/get_data/param_global.py] [deal_param_name_tuple ][__file__:59]- 处理接口请求参数名出现异常，异常原因：list index out of range
2019-09-18 15:10:35,906 [ERROR] [/home/ma/PycharmProjects/Auto_InterFace_GUI/InterfaceTest/python_excel/get_data/param_global.py] [deal_param_name_tuple ][__file__:59]- 处理接口请求参数名出现异常，异常原因：list index out of range
2019-09-18 15:10:35,906 [ERROR] [/home/ma/PycharmProjects/Auto_InterFace_GUI/InterfaceTest/python_excel/get_data/param_global.py] [deal_param_name_tuple ][__file__:59]- 处理接口请求参数名出现异常，异常原因：list index out of range
2019-09-18 15:10:41,934 [ERROR] [/home/ma/PycharmProjects/Auto_InterFace_GUI/InterfaceTest/python_excel/get_data/param_global.py] [deal_param_name_tuple ][__file__:59]- 处理接口请求参数名出现异常，异常原因：list index out of range
2019-09-18 15:10:42,096 [ERROR] [/home/ma/PycharmProjects/Auto_InterFace_GUI/InterfaceTest/python_excel/common/cmp_res_req.py] [verify_database ][/home/ma/PycharmProjects/Auto_InterFace_GUI/InterfaceTest/python_excel/common/cmp_res_req.py:162]- 测试用例请求参数与存储结果对比出现异常，异常原因：'Response' object has no attribute 'get'
2019-09-18 15:10:42,096 [ERROR] [/home/ma/PycharmProjects/Auto_InterFace_GUI/InterfaceTest/python_excel/common/cmp_res_req.py] [verify_is_pass ][/home/ma/PycharmProjects/Auto_InterFace_GUI/InterfaceTest/python_excel/common/cmp_res_req.py:74]- 测试用例预期结果与实际结果对比方法出现异常，异常原因：local variable 'callbackurl_flag' referenced before assignment
2019-09-18 15:11:37,918 [ERROR] [/home/ma/PycharmProjects/Auto_InterFace_GUI/InterfaceTest/python_excel/get_data/param_global.py] [deal_param_name_tuple ][__file__:59]- 处理接口请求参数名出现异常，异常原因：list index out of range
2019-09-18 15:11:38,101 [ERROR] [/home/ma/PycharmProjects/Auto_InterFace_GUI/InterfaceTest/python_excel/common/cmp_res_req.py] [verify_database ][/home/ma/PycharmProjects/Auto_InterFace_GUI/InterfaceTest/python_excel/common/cmp_res_req.py:162]- 测试用例请求参数与存储结果对比出现异常，异常原因：'Response' object has no attribute 'get'
2019-09-18 15:11:38,101 [ERROR] [/home/ma/PycharmProjects/Auto_InterFace_GUI/InterfaceTest/python_excel/common/cmp_res_req.py] [verify_is_pass ][/home/ma/PycharmProjects/Auto_InterFace_GUI/InterfaceTest/python_excel/common/cmp_res_req.py:74]- 测试用例预期结果与实际结果对比方法出现异常，异常原因：local variable 'callbackurl_flag' referenced before assignment
2019-09-18 15:12:15,242 [ERROR] [/home/ma/PycharmProjects/Auto_InterFace_GUI/InterfaceTest/python_excel/get_data/param_global.py] [deal_param_name_tuple ][__file__:59]- 处理接口请求参数名出现异常，异常原因：list index out of range
2019-09-18 15:12:15,414 [ERROR] [/home/ma/PycharmProjects/Auto_InterFace_GUI/InterfaceTest/python_excel/get_data/param_global.py] [deal_param_name_tuple ][__file__:59]- 处理接口请求参数名出现异常，异常原因：list index out of range
2019-09-18 15:12:15,414 [ERROR] [/home/ma/PycharmProjects/Auto_InterFace_GUI/InterfaceTest/python_excel/get_data/param_global.py] [deal_param_name_tuple ][__file__:59]- 处理接口请求参数名出现异常，异常原因：list index out of range
2019-09-18 15:12:19,104 [ERROR] [/home/ma/PycharmProjects/Auto_InterFace_GUI/InterfaceTest/python_excel/get_data/param_global.py] [deal_param_name_tuple ][__file__:59]- 处理接口请求参数名出现异常，异常原因：list index out of range
2019-09-18 15:12:19,267 [ERROR] [/home/ma/PycharmProjects/Auto_InterFace_GUI/InterfaceTest/python_excel/common/cmp_res_req.py] [verify_database ][/home/ma/PycharmProjects/Auto_InterFace_GUI/InterfaceTest/python_excel/common/cmp_res_req.py:162]- 测试用例请求参数与存储结果对比出现异常，异常原因：'Response' object has no attribute 'get'
2019-09-18 15:12:19,267 [ERROR] [/home/ma/PycharmProjects/Auto_InterFace_GUI/InterfaceTest/python_excel/common/cmp_res_req.py] [verify_is_pass ][/home/ma/PycharmProjects/Auto_InterFace_GUI/InterfaceTest/python_excel/common/cmp_res_req.py:74]- 测试用例预期结果与实际结果对比方法出现异常，异常原因：local variable 'callbackurl_flag' referenced before assignment
2019-09-18 15:13:46,404 [ERROR] [/home/ma/PycharmProjects/Auto_InterFace_GUI/InterfaceTest/python_excel/get_data/param_global.py] [deal_param_name_tuple ][__file__:59]- 处理接口请求参数名出现异常，异常原因：list index out of range
2019-09-18 15:13:46,568 [ERROR] [/home/ma/PycharmProjects/Auto_InterFace_GUI/InterfaceTest/python_excel/get_data/param_global.py] [deal_param_name_tuple ][__file__:59]- 处理接口请求参数名出现异常，异常原因：list index out of range
2019-09-18 15:13:46,568 [ERROR] [/home/ma/PycharmProjects/Auto_InterFace_GUI/InterfaceTest/python_excel/get_data/param_global.py] [deal_param_name_tuple ][__file__:59]- 处理接口请求参数名出现异常，异常原因：list index out of range
2019-09-18 15:13:48,841 [ERROR] [/home/ma/PycharmProjects/Auto_InterFace_GUI/InterfaceTest/python_excel/get_data/param_global.py] [deal_param_name_tuple ][__file__:59]- 处理接口请求参数名出现异常，异常原因：list index out of range
2019-09-18 15:15:02,938 [ERROR] [/home/ma/PycharmProjects/Auto_InterFace_GUI/InterfaceTest/python_excel/common/cmp_res_req.py] [verify_database ][/home/ma/PycharmProjects/Auto_InterFace_GUI/InterfaceTest/python_excel/common/cmp_res_req.py:162]- 测试用例请求参数与存储结果对比出现异常，异常原因：'Response' object has no attribute 'get'
2019-09-18 15:15:02,938 [ERROR] [/home/ma/PycharmProjects/Auto_InterFace_GUI/InterfaceTest/python_excel/common/cmp_res_req.py] [verify_is_pass ][/home/ma/PycharmProjects/Auto_InterFace_GUI/InterfaceTest/python_excel/common/cmp_res_req.py:74]- 测试用例预期结果与实际结果对比方法出现异常，异常原因：local variable 'callbackurl_flag' referenced before assignment
2019-09-18 15:15:08,434 [INFO] [/home/ma/PycharmProjects/Auto_InterFace_GUI/venv/lib/python3.6/site-packages/django/utils/autoreload.py] [trigger_reload ][django.utils.autoreload:217]- /home/ma/PycharmProjects/Auto_InterFace_GUI/InterfaceTest/python_excel/common/cmp_res_req.py changed, reloading.
2019-09-18 15:15:24,779 [ERROR] [/home/ma/PycharmProjects/Auto_InterFace_GUI/InterfaceTest/python_excel/get_data/param_global.py] [deal_param_name_tuple ][__file__:59]- 处理接口请求参数名出现异常，异常原因：list index out of range
2019-09-18 15:15:24,943 [ERROR] [/home/ma/PycharmProjects/Auto_InterFace_GUI/InterfaceTest/python_excel/get_data/param_global.py] [deal_param_name_tuple ][__file__:59]- 处理接口请求参数名出现异常，异常原因：list index out of range
2019-09-18 15:15:24,943 [ERROR] [/home/ma/PycharmProjects/Auto_InterFace_GUI/InterfaceTest/python_excel/get_data/param_global.py] [deal_param_name_tuple ][__file__:59]- 处理接口请求参数名出现异常，异常原因：list index out of range
2019-09-18 15:15:29,110 [ERROR] [/home/ma/PycharmProjects/Auto_InterFace_GUI/InterfaceTest/python_excel/get_data/param_global.py] [deal_param_name_tuple ][__file__:59]- 处理接口请求参数名出现异常，异常原因：list index out of range
2019-09-18 15:17:16,094 [ERROR] [/home/ma/PycharmProjects/Auto_InterFace_GUI/InterfaceTest/python_excel/get_data/param_global.py] [deal_param_name_tuple ][__file__:59]- 处理接口请求参数名出现异常，异常原因：list index out of range
2019-09-18 15:17:16,254 [ERROR] [/home/ma/PycharmProjects/Auto_InterFace_GUI/InterfaceTest/python_excel/get_data/param_global.py] [deal_param_name_tuple ][__file__:59]- 处理接口请求参数名出现异常，异常原因：list index out of range
2019-09-18 15:17:16,255 [ERROR] [/home/ma/PycharmProjects/Auto_InterFace_GUI/InterfaceTest/python_excel/get_data/param_global.py] [deal_param_name_tuple ][__file__:59]- 处理接口请求参数名出现异常，异常原因：list index out of range
2019-09-18 15:17:18,391 [ERROR] [/home/ma/PycharmProjects/Auto_InterFace_GUI/InterfaceTest/python_excel/get_data/param_global.py] [deal_param_name_tuple ][__file__:59]- 处理接口请求参数名出现异常，异常原因：list index out of range
2019-09-18 15:17:24,376 [INFO] [/home/ma/PycharmProjects/Auto_InterFace_GUI/venv/lib/python3.6/site-packages/elasticsearch/connection/base.py] [log_request_success ][elasticsearch:121]- GET http://39.107.66.190:9200/evidence/_search [status:200 request:0.048s]
2019-09-18 15:17:24,384 [ERROR] [/home/ma/PycharmProjects/Auto_InterFace_GUI/InterfaceTest/python_excel/common/cmp_res_req.py] [verify_database ][/home/ma/PycharmProjects/Auto_InterFace_GUI/InterfaceTest/python_excel/common/cmp_res_req.py:162]- 测试用例请求参数与存储结果对比出现异常，异常原因：'bool' object is not subscriptable
2019-09-18 15:17:24,384 [ERROR] [/home/ma/PycharmProjects/Auto_InterFace_GUI/InterfaceTest/python_excel/common/cmp_res_req.py] [verify_is_pass ][/home/ma/PycharmProjects/Auto_InterFace_GUI/InterfaceTest/python_excel/common/cmp_res_req.py:74]- 测试用例预期结果与实际结果对比方法出现异常，异常原因：local variable 'callbackurl_flag' referenced before assignment
2019-09-18 15:18:04,542 [ERROR] [/home/ma/PycharmProjects/Auto_InterFace_GUI/InterfaceTest/python_excel/get_data/param_global.py] [deal_param_name_tuple ][__file__:59]- 处理接口请求参数名出现异常，异常原因：list index out of range
2019-09-18 15:18:04,780 [INFO] [/home/ma/PycharmProjects/Auto_InterFace_GUI/venv/lib/python3.6/site-packages/elasticsearch/connection/base.py] [log_request_success ][elasticsearch:121]- GET http://39.107.66.190:9200/evidence/_search [status:200 request:0.052s]
2019-09-18 15:18:04,795 [ERROR] [/home/ma/PycharmProjects/Auto_InterFace_GUI/InterfaceTest/python_excel/common/cmp_res_req.py] [verify_database ][/home/ma/PycharmProjects/Auto_InterFace_GUI/InterfaceTest/python_excel/common/cmp_res_req.py:162]- 测试用例请求参数与存储结果对比出现异常，异常原因：'bool' object is not subscriptable
2019-09-18 15:18:04,795 [ERROR] [/home/ma/PycharmProjects/Auto_InterFace_GUI/InterfaceTest/python_excel/common/cmp_res_req.py] [verify_is_pass ][/home/ma/PycharmProjects/Auto_InterFace_GUI/InterfaceTest/python_excel/common/cmp_res_req.py:74]- 测试用例预期结果与实际结果对比方法出现异常，异常原因：local variable 'callbackurl_flag' referenced before assignment
2019-09-18 15:18:36,999 [ERROR] [/home/ma/PycharmProjects/Auto_InterFace_GUI/InterfaceTest/python_excel/get_data/param_global.py] [deal_param_name_tuple ][__file__:59]- 处理接口请求参数名出现异常，异常原因：list index out of range
2019-09-18 15:18:37,159 [ERROR] [/home/ma/PycharmProjects/Auto_InterFace_GUI/InterfaceTest/python_excel/get_data/param_global.py] [deal_param_name_tuple ][__file__:59]- 处理接口请求参数名出现异常，异常原因：list index out of range
2019-09-18 15:18:37,159 [ERROR] [/home/ma/PycharmProjects/Auto_InterFace_GUI/InterfaceTest/python_excel/get_data/param_global.py] [deal_param_name_tuple ][__file__:59]- 处理接口请求参数名出现异常，异常原因：list index out of range
2019-09-18 15:18:46,468 [ERROR] [/home/ma/PycharmProjects/Auto_InterFace_GUI/InterfaceTest/python_excel/get_data/param_global.py] [deal_param_name_tuple ][__file__:59]- 处理接口请求参数名出现异常，异常原因：list index out of range
2019-09-18 15:19:12,636 [INFO] [/home/ma/PycharmProjects/Auto_InterFace_GUI/venv/lib/python3.6/site-packages/elasticsearch/connection/base.py] [log_request_success ][elasticsearch:121]- GET http://39.107.66.190:9200/evidence/_search [status:200 request:0.047s]
2019-09-18 15:20:59,583 [ERROR] [/home/ma/PycharmProjects/Auto_InterFace_GUI/InterfaceTest/python_excel/get_data/param_global.py] [deal_param_name_tuple ][__file__:59]- 处理接口请求参数名出现异常，异常原因：list index out of range
2019-09-18 15:20:59,754 [ERROR] [/home/ma/PycharmProjects/Auto_InterFace_GUI/InterfaceTest/python_excel/get_data/param_global.py] [deal_param_name_tuple ][__file__:59]- 处理接口请求参数名出现异常，异常原因：list index out of range
2019-09-18 15:20:59,754 [ERROR] [/home/ma/PycharmProjects/Auto_InterFace_GUI/InterfaceTest/python_excel/get_data/param_global.py] [deal_param_name_tuple ][__file__:59]- 处理接口请求参数名出现异常，异常原因：list index out of range
2019-09-18 15:21:05,332 [ERROR] [/home/ma/PycharmProjects/Auto_InterFace_GUI/InterfaceTest/python_excel/get_data/param_global.py] [deal_param_name_tuple ][__file__:59]- 处理接口请求参数名出现异常，异常原因：list index out of range
2019-09-18 15:21:18,591 [INFO] [/home/ma/PycharmProjects/Auto_InterFace_GUI/venv/lib/python3.6/site-packages/elasticsearch/connection/base.py] [log_request_success ][elasticsearch:121]- GET http://39.107.66.190:9200/evidence/_search [status:200 request:0.048s]
2019-09-18 15:23:33,354 [ERROR] [/home/ma/PycharmProjects/Auto_InterFace_GUI/InterfaceTest/python_excel/get_data/param_global.py] [deal_param_name_tuple ][__file__:59]- 处理接口请求参数名出现异常，异常原因：list index out of range
2019-09-18 15:23:34,324 [INFO] [/home/ma/PycharmProjects/Auto_InterFace_GUI/venv/lib/python3.6/site-packages/elasticsearch/connection/base.py] [log_request_success ][elasticsearch:121]- GET http://39.107.66.190:9200/evidence/_search [status:200 request:0.054s]
2019-09-18 15:29:24,936 [INFO] [/home/ma/PycharmProjects/Auto_InterFace_GUI/venv/lib/python3.6/site-packages/django/utils/autoreload.py] [trigger_reload ][django.utils.autoreload:217]- /home/ma/PycharmProjects/Auto_InterFace_GUI/upload_case/views.py changed, reloading.
2019-09-18 16:16:16,908 [ERROR] [/home/ma/PycharmProjects/Auto_InterFace_GUI/InterfaceTest/python_excel/utils/operation_json.py] [read_data ][/home/ma/PycharmProjects/Auto_InterFace_GUI/InterfaceTest/python_excel/utils/operation_json.py:25]- 操作JSON类读取数据异常，异常原因：Extra data: line 5 column 2 (char 391)
2019-09-18 16:16:16,909 [ERROR] [/home/ma/PycharmProjects/Auto_InterFace_GUI/InterfaceTest/python_excel/utils/operation_json.py] [read_data ][/home/ma/PycharmProjects/Auto_InterFace_GUI/InterfaceTest/python_excel/utils/operation_json.py:25]- 操作JSON类读取数据异常，异常原因：Extra data: line 5 column 2 (char 391)
2019-09-18 16:16:16,909 [ERROR] [/home/ma/PycharmProjects/Auto_InterFace_GUI/InterfaceTest/python_excel/utils/operation_json.py] [get_data_for_key ][/home/ma/PycharmProjects/Auto_InterFace_GUI/InterfaceTest/python_excel/utils/operation_json.py:39]- 操作JSON类根据key获取value异常，异常原因：'NoneType' object is not subscriptable
2019-09-18 16:16:16,909 [ERROR] [/home/ma/PycharmProjects/Auto_InterFace_GUI/InterfaceTest/python_excel/utils/operation_json.py] [read_data ][/home/ma/PycharmProjects/Auto_InterFace_GUI/InterfaceTest/python_excel/utils/operation_json.py:25]- 操作JSON类读取数据异常，异常原因：Extra data: line 5 column 2 (char 391)
2019-09-18 16:16:16,910 [ERROR] [/home/ma/PycharmProjects/Auto_InterFace_GUI/InterfaceTest/python_excel/utils/operation_json.py] [get_data_for_key ][/home/ma/PycharmProjects/Auto_InterFace_GUI/InterfaceTest/python_excel/utils/operation_json.py:39]- 操作JSON类根据key获取value异常，异常原因：'NoneType' object is not subscriptable
2019-09-18 16:16:16,910 [ERROR] [/home/ma/PycharmProjects/Auto_InterFace_GUI/InterfaceTest/python_excel/utils/operation_json.py] [read_data ][/home/ma/PycharmProjects/Auto_InterFace_GUI/InterfaceTest/python_excel/utils/operation_json.py:25]- 操作JSON类读取数据异常，异常原因：Extra data: line 5 column 2 (char 391)
2019-09-18 16:16:16,910 [ERROR] [/home/ma/PycharmProjects/Auto_InterFace_GUI/InterfaceTest/python_excel/utils/operation_json.py] [get_data_for_key ][/home/ma/PycharmProjects/Auto_InterFace_GUI/InterfaceTest/python_excel/utils/operation_json.py:39]- 操作JSON类根据key获取value异常，异常原因：'NoneType' object is not subscriptable
2019-09-18 16:16:16,911 [ERROR] [/home/ma/PycharmProjects/Auto_InterFace_GUI/InterfaceTest/python_excel/utils/operation_cfg.py] [read_cfg ][__file__:31]- 读取cfg配置文件内容异常，异常原因：'NoneType' object is not iterable
2019-09-18 16:16:16,911 [ERROR] [/home/ma/PycharmProjects/Auto_InterFace_GUI/InterfaceTest/python_excel/utils/operation_cfg.py] [get_section_option_list ][__file__:82]- 读取配置文件指定段section下所有option列表出现异常，异常原因：No section: 'my_case_file'
2019-09-18 16:16:21,389 [ERROR] [/home/ma/PycharmProjects/Auto_InterFace_GUI/venv/lib/python3.6/site-packages/django/utils/log.py] [log_response ][django.request:228]- Internal Server Error: /
Traceback (most recent call last):
  File "/home/ma/PycharmProjects/Auto_InterFace_GUI/venv/lib/python3.6/site-packages/django/core/handlers/exception.py", line 34, in inner
    response = get_response(request)
  File "/home/ma/PycharmProjects/Auto_InterFace_GUI/venv/lib/python3.6/site-packages/django/core/handlers/base.py", line 115, in _get_response
    response = self.process_exception_by_middleware(e, request)
  File "/home/ma/PycharmProjects/Auto_InterFace_GUI/venv/lib/python3.6/site-packages/django/core/handlers/base.py", line 113, in _get_response
    response = wrapped_callback(request, *callback_args, **callback_kwargs)
  File "/home/ma/PycharmProjects/Auto_InterFace_GUI/upload_case/views.py", line 49, in index
    from upload_case import case_test_common
  File "/home/ma/PycharmProjects/Auto_InterFace_GUI/upload_case/case_test_common.py", line 37, in <module>
    filename = option_dict["case_filepath"]
KeyError: 'case_filepath'
2019-09-18 16:17:33,857 [ERROR] [/home/ma/PycharmProjects/Auto_InterFace_GUI/InterfaceTest/python_excel/utils/operation_json.py] [read_data ][/home/ma/PycharmProjects/Auto_InterFace_GUI/InterfaceTest/python_excel/utils/operation_json.py:25]- 操作JSON类读取数据异常，异常原因：Extra data: line 5 column 2 (char 391)
2019-09-18 16:17:33,858 [ERROR] [/home/ma/PycharmProjects/Auto_InterFace_GUI/InterfaceTest/python_excel/utils/operation_json.py] [read_data ][/home/ma/PycharmProjects/Auto_InterFace_GUI/InterfaceTest/python_excel/utils/operation_json.py:25]- 操作JSON类读取数据异常，异常原因：Extra data: line 5 column 2 (char 391)
2019-09-18 16:17:33,858 [ERROR] [/home/ma/PycharmProjects/Auto_InterFace_GUI/InterfaceTest/python_excel/utils/operation_json.py] [get_data_for_key ][/home/ma/PycharmProjects/Auto_InterFace_GUI/InterfaceTest/python_excel/utils/operation_json.py:39]- 操作JSON类根据key获取value异常，异常原因：'NoneType' object is not subscriptable
2019-09-18 16:17:33,859 [ERROR] [/home/ma/PycharmProjects/Auto_InterFace_GUI/InterfaceTest/python_excel/utils/operation_json.py] [read_data ][/home/ma/PycharmProjects/Auto_InterFace_GUI/InterfaceTest/python_excel/utils/operation_json.py:25]- 操作JSON类读取数据异常，异常原因：Extra data: line 5 column 2 (char 391)
2019-09-18 16:17:33,859 [ERROR] [/home/ma/PycharmProjects/Auto_InterFace_GUI/InterfaceTest/python_excel/utils/operation_json.py] [get_data_for_key ][/home/ma/PycharmProjects/Auto_InterFace_GUI/InterfaceTest/python_excel/utils/operation_json.py:39]- 操作JSON类根据key获取value异常，异常原因：'NoneType' object is not subscriptable
2019-09-18 16:17:33,859 [ERROR] [/home/ma/PycharmProjects/Auto_InterFace_GUI/InterfaceTest/python_excel/utils/operation_json.py] [read_data ][/home/ma/PycharmProjects/Auto_InterFace_GUI/InterfaceTest/python_excel/utils/operation_json.py:25]- 操作JSON类读取数据异常，异常原因：Extra data: line 5 column 2 (char 391)
2019-09-18 16:17:33,859 [ERROR] [/home/ma/PycharmProjects/Auto_InterFace_GUI/InterfaceTest/python_excel/utils/operation_json.py] [get_data_for_key ][/home/ma/PycharmProjects/Auto_InterFace_GUI/InterfaceTest/python_excel/utils/operation_json.py:39]- 操作JSON类根据key获取value异常，异常原因：'NoneType' object is not subscriptable
2019-09-18 16:17:33,859 [ERROR] [/home/ma/PycharmProjects/Auto_InterFace_GUI/InterfaceTest/python_excel/utils/operation_cfg.py] [read_cfg ][__file__:31]- 读取cfg配置文件内容异常，异常原因：'NoneType' object is not iterable
2019-09-18 16:17:33,860 [ERROR] [/home/ma/PycharmProjects/Auto_InterFace_GUI/InterfaceTest/python_excel/utils/operation_cfg.py] [get_section_option_list ][__file__:82]- 读取配置文件指定段section下所有option列表出现异常，异常原因：No section: 'my_case_file'
2019-09-18 16:21:19,968 [ERROR] [/home/ma/PycharmProjects/Auto_InterFace_GUI/InterfaceTest/python_excel/utils/operation_json.py] [read_data ][/home/ma/PycharmProjects/Auto_InterFace_GUI/InterfaceTest/python_excel/utils/operation_json.py:25]- 操作JSON类读取数据异常，异常原因：Extra data: line 5 column 2 (char 391)
2019-09-18 16:21:19,968 [ERROR] [/home/ma/PycharmProjects/Auto_InterFace_GUI/InterfaceTest/python_excel/utils/operation_json.py] [read_data ][/home/ma/PycharmProjects/Auto_InterFace_GUI/InterfaceTest/python_excel/utils/operation_json.py:25]- 操作JSON类读取数据异常，异常原因：Extra data: line 5 column 2 (char 391)
2019-09-18 16:21:19,969 [ERROR] [/home/ma/PycharmProjects/Auto_InterFace_GUI/InterfaceTest/python_excel/utils/operation_json.py] [get_data_for_key ][/home/ma/PycharmProjects/Auto_InterFace_GUI/InterfaceTest/python_excel/utils/operation_json.py:39]- 操作JSON类根据key获取value异常，异常原因：'NoneType' object is not subscriptable
2019-09-18 16:21:19,969 [ERROR] [/home/ma/PycharmProjects/Auto_InterFace_GUI/InterfaceTest/python_excel/utils/operation_json.py] [read_data ][/home/ma/PycharmProjects/Auto_InterFace_GUI/InterfaceTest/python_excel/utils/operation_json.py:25]- 操作JSON类读取数据异常，异常原因：Extra data: line 5 column 2 (char 391)
2019-09-18 16:21:19,969 [ERROR] [/home/ma/PycharmProjects/Auto_InterFace_GUI/InterfaceTest/python_excel/utils/operation_json.py] [get_data_for_key ][/home/ma/PycharmProjects/Auto_InterFace_GUI/InterfaceTest/python_excel/utils/operation_json.py:39]- 操作JSON类根据key获取value异常，异常原因：'NoneType' object is not subscriptable
2019-09-18 16:21:19,969 [ERROR] [/home/ma/PycharmProjects/Auto_InterFace_GUI/InterfaceTest/python_excel/utils/operation_json.py] [read_data ][/home/ma/PycharmProjects/Auto_InterFace_GUI/InterfaceTest/python_excel/utils/operation_json.py:25]- 操作JSON类读取数据异常，异常原因：Extra data: line 5 column 2 (char 391)
2019-09-18 16:21:19,969 [ERROR] [/home/ma/PycharmProjects/Auto_InterFace_GUI/InterfaceTest/python_excel/utils/operation_json.py] [get_data_for_key ][/home/ma/PycharmProjects/Auto_InterFace_GUI/InterfaceTest/python_excel/utils/operation_json.py:39]- 操作JSON类根据key获取value异常，异常原因：'NoneType' object is not subscriptable
2019-09-18 16:21:19,969 [ERROR] [/home/ma/PycharmProjects/Auto_InterFace_GUI/InterfaceTest/python_excel/utils/operation_cfg.py] [read_cfg ][__file__:31]- 读取cfg配置文件内容异常，异常原因：'NoneType' object is not iterable
2019-09-18 16:21:19,970 [ERROR] [/home/ma/PycharmProjects/Auto_InterFace_GUI/InterfaceTest/python_excel/utils/operation_cfg.py] [get_section_option_list ][__file__:82]- 读取配置文件指定段section下所有option列表出现异常，异常原因：No section: 'my_case_file'
2019-09-18 16:21:21,428 [ERROR] [/home/ma/PycharmProjects/Auto_InterFace_GUI/venv/lib/python3.6/site-packages/django/utils/log.py] [log_response ][django.request:228]- Internal Server Error: /
Traceback (most recent call last):
  File "/home/ma/PycharmProjects/Auto_InterFace_GUI/venv/lib/python3.6/site-packages/django/core/handlers/exception.py", line 34, in inner
    response = get_response(request)
  File "/home/ma/PycharmProjects/Auto_InterFace_GUI/venv/lib/python3.6/site-packages/django/core/handlers/base.py", line 115, in _get_response
    response = self.process_exception_by_middleware(e, request)
  File "/home/ma/PycharmProjects/Auto_InterFace_GUI/venv/lib/python3.6/site-packages/django/core/handlers/base.py", line 113, in _get_response
    response = wrapped_callback(request, *callback_args, **callback_kwargs)
  File "/home/ma/PycharmProjects/Auto_InterFace_GUI/upload_case/views.py", line 49, in index
    from upload_case import case_test_common
  File "/home/ma/PycharmProjects/Auto_InterFace_GUI/upload_case/case_test_common.py", line 37, in <module>
    filename = option_dict["case_filepath"]
KeyError: 'case_filepath'
2019-09-18 16:23:05,122 [ERROR] [/home/ma/PycharmProjects/Auto_InterFace_GUI/InterfaceTest/python_excel/utils/operation_json.py] [read_data ][/home/ma/PycharmProjects/Auto_InterFace_GUI/InterfaceTest/python_excel/utils/operation_json.py:25]- 操作JSON类读取数据异常，异常原因：Extra data: line 5 column 2 (char 391)
2019-09-18 16:23:05,122 [ERROR] [/home/ma/PycharmProjects/Auto_InterFace_GUI/InterfaceTest/python_excel/utils/operation_json.py] [read_data ][/home/ma/PycharmProjects/Auto_InterFace_GUI/InterfaceTest/python_excel/utils/operation_json.py:25]- 操作JSON类读取数据异常，异常原因：Extra data: line 5 column 2 (char 391)
2019-09-18 16:23:05,122 [ERROR] [/home/ma/PycharmProjects/Auto_InterFace_GUI/InterfaceTest/python_excel/utils/operation_json.py] [get_data_for_key ][/home/ma/PycharmProjects/Auto_InterFace_GUI/InterfaceTest/python_excel/utils/operation_json.py:39]- 操作JSON类根据key获取value异常，异常原因：'NoneType' object is not subscriptable
2019-09-18 16:23:05,123 [ERROR] [/home/ma/PycharmProjects/Auto_InterFace_GUI/InterfaceTest/python_excel/utils/operation_json.py] [read_data ][/home/ma/PycharmProjects/Auto_InterFace_GUI/InterfaceTest/python_excel/utils/operation_json.py:25]- 操作JSON类读取数据异常，异常原因：Extra data: line 5 column 2 (char 391)
2019-09-18 16:23:05,123 [ERROR] [/home/ma/PycharmProjects/Auto_InterFace_GUI/InterfaceTest/python_excel/utils/operation_json.py] [get_data_for_key ][/home/ma/PycharmProjects/Auto_InterFace_GUI/InterfaceTest/python_excel/utils/operation_json.py:39]- 操作JSON类根据key获取value异常，异常原因：'NoneType' object is not subscriptable
2019-09-18 16:23:05,123 [ERROR] [/home/ma/PycharmProjects/Auto_InterFace_GUI/InterfaceTest/python_excel/utils/operation_json.py] [read_data ][/home/ma/PycharmProjects/Auto_InterFace_GUI/InterfaceTest/python_excel/utils/operation_json.py:25]- 操作JSON类读取数据异常，异常原因：Extra data: line 5 column 2 (char 391)
2019-09-18 16:23:05,123 [ERROR] [/home/ma/PycharmProjects/Auto_InterFace_GUI/InterfaceTest/python_excel/utils/operation_json.py] [get_data_for_key ][/home/ma/PycharmProjects/Auto_InterFace_GUI/InterfaceTest/python_excel/utils/operation_json.py:39]- 操作JSON类根据key获取value异常，异常原因：'NoneType' object is not subscriptable
2019-09-18 16:23:05,123 [ERROR] [/home/ma/PycharmProjects/Auto_InterFace_GUI/InterfaceTest/python_excel/utils/operation_cfg.py] [read_cfg ][__file__:31]- 读取cfg配置文件内容异常，异常原因：'NoneType' object is not iterable
2019-09-18 16:23:05,123 [ERROR] [/home/ma/PycharmProjects/Auto_InterFace_GUI/InterfaceTest/python_excel/utils/operation_cfg.py] [get_section_option_list ][__file__:82]- 读取配置文件指定段section下所有option列表出现异常，异常原因：No section: 'my_case_file'
2019-09-18 16:23:06,418 [ERROR] [/home/ma/PycharmProjects/Auto_InterFace_GUI/venv/lib/python3.6/site-packages/django/utils/log.py] [log_response ][django.request:228]- Internal Server Error: /
Traceback (most recent call last):
  File "/home/ma/PycharmProjects/Auto_InterFace_GUI/venv/lib/python3.6/site-packages/django/core/handlers/exception.py", line 34, in inner
    response = get_response(request)
  File "/home/ma/PycharmProjects/Auto_InterFace_GUI/venv/lib/python3.6/site-packages/django/core/handlers/base.py", line 115, in _get_response
    response = self.process_exception_by_middleware(e, request)
  File "/home/ma/PycharmProjects/Auto_InterFace_GUI/venv/lib/python3.6/site-packages/django/core/handlers/base.py", line 113, in _get_response
    response = wrapped_callback(request, *callback_args, **callback_kwargs)
  File "/home/ma/PycharmProjects/Auto_InterFace_GUI/upload_case/views.py", line 49, in index
    from upload_case import case_test_common
  File "/home/ma/PycharmProjects/Auto_InterFace_GUI/upload_case/case_test_common.py", line 37, in <module>
    filename = option_dict["case_filepath"]
KeyError: 'case_filepath'
2019-09-18 16:24:37,593 [ERROR] [/home/ma/PycharmProjects/Auto_InterFace_GUI/InterfaceTest/python_excel/utils/operation_json.py] [read_data ][/home/ma/PycharmProjects/Auto_InterFace_GUI/InterfaceTest/python_excel/utils/operation_json.py:25]- 操作JSON类读取数据异常，异常原因：Extra data: line 5 column 2 (char 389)
2019-09-18 16:24:37,594 [ERROR] [/home/ma/PycharmProjects/Auto_InterFace_GUI/InterfaceTest/python_excel/utils/operation_json.py] [read_data ][/home/ma/PycharmProjects/Auto_InterFace_GUI/InterfaceTest/python_excel/utils/operation_json.py:25]- 操作JSON类读取数据异常，异常原因：Extra data: line 5 column 2 (char 389)
2019-09-18 16:24:37,595 [ERROR] [/home/ma/PycharmProjects/Auto_InterFace_GUI/InterfaceTest/python_excel/utils/operation_json.py] [get_data_for_key ][/home/ma/PycharmProjects/Auto_InterFace_GUI/InterfaceTest/python_excel/utils/operation_json.py:39]- 操作JSON类根据key获取value异常，异常原因：'NoneType' object is not subscriptable
2019-09-18 16:24:37,596 [ERROR] [/home/ma/PycharmProjects/Auto_InterFace_GUI/InterfaceTest/python_excel/utils/operation_json.py] [read_data ][/home/ma/PycharmProjects/Auto_InterFace_GUI/InterfaceTest/python_excel/utils/operation_json.py:25]- 操作JSON类读取数据异常，异常原因：Extra data: line 5 column 2 (char 389)
2019-09-18 16:24:37,596 [ERROR] [/home/ma/PycharmProjects/Auto_InterFace_GUI/InterfaceTest/python_excel/utils/operation_json.py] [get_data_for_key ][/home/ma/PycharmProjects/Auto_InterFace_GUI/InterfaceTest/python_excel/utils/operation_json.py:39]- 操作JSON类根据key获取value异常，异常原因：'NoneType' object is not subscriptable
2019-09-18 16:24:37,597 [ERROR] [/home/ma/PycharmProjects/Auto_InterFace_GUI/InterfaceTest/python_excel/utils/operation_json.py] [read_data ][/home/ma/PycharmProjects/Auto_InterFace_GUI/InterfaceTest/python_excel/utils/operation_json.py:25]- 操作JSON类读取数据异常，异常原因：Extra data: line 5 column 2 (char 389)
2019-09-18 16:24:37,598 [ERROR] [/home/ma/PycharmProjects/Auto_InterFace_GUI/InterfaceTest/python_excel/utils/operation_json.py] [get_data_for_key ][/home/ma/PycharmProjects/Auto_InterFace_GUI/InterfaceTest/python_excel/utils/operation_json.py:39]- 操作JSON类根据key获取value异常，异常原因：'NoneType' object is not subscriptable
2019-09-18 16:24:37,598 [ERROR] [/home/ma/PycharmProjects/Auto_InterFace_GUI/InterfaceTest/python_excel/utils/operation_cfg.py] [read_cfg ][__file__:31]- 读取cfg配置文件内容异常，异常原因：'NoneType' object is not iterable
2019-09-18 16:24:37,599 [ERROR] [/home/ma/PycharmProjects/Auto_InterFace_GUI/InterfaceTest/python_excel/utils/operation_cfg.py] [get_section_option_list ][__file__:82]- 读取配置文件指定段section下所有option列表出现异常，异常原因：No section: 'my_case_file'
2019-09-18 16:24:38,776 [ERROR] [/home/ma/PycharmProjects/Auto_InterFace_GUI/venv/lib/python3.6/site-packages/django/utils/log.py] [log_response ][django.request:228]- Internal Server Error: /
Traceback (most recent call last):
  File "/home/ma/PycharmProjects/Auto_InterFace_GUI/venv/lib/python3.6/site-packages/django/core/handlers/exception.py", line 34, in inner
    response = get_response(request)
  File "/home/ma/PycharmProjects/Auto_InterFace_GUI/venv/lib/python3.6/site-packages/django/core/handlers/base.py", line 115, in _get_response
    response = self.process_exception_by_middleware(e, request)
  File "/home/ma/PycharmProjects/Auto_InterFace_GUI/venv/lib/python3.6/site-packages/django/core/handlers/base.py", line 113, in _get_response
    response = wrapped_callback(request, *callback_args, **callback_kwargs)
  File "/home/ma/PycharmProjects/Auto_InterFace_GUI/upload_case/views.py", line 49, in index
    from upload_case import case_test_common
  File "/home/ma/PycharmProjects/Auto_InterFace_GUI/upload_case/case_test_common.py", line 37, in <module>
    filename = option_dict["case_filepath"]
KeyError: 'case_filepath'
2019-09-18 16:28:54,935 [ERROR] [/home/ma/PycharmProjects/Auto_InterFace_GUI/InterfaceTest/python_excel/utils/operation_json.py] [read_data ][/home/ma/PycharmProjects/Auto_InterFace_GUI/InterfaceTest/python_excel/utils/operation_json.py:25]- 操作JSON类读取数据异常，异常原因：Extra data: line 5 column 2 (char 391)
2019-09-18 16:28:54,936 [ERROR] [/home/ma/PycharmProjects/Auto_InterFace_GUI/InterfaceTest/python_excel/utils/operation_json.py] [read_data ][/home/ma/PycharmProjects/Auto_InterFace_GUI/InterfaceTest/python_excel/utils/operation_json.py:25]- 操作JSON类读取数据异常，异常原因：Extra data: line 5 column 2 (char 391)
2019-09-18 16:28:54,936 [ERROR] [/home/ma/PycharmProjects/Auto_InterFace_GUI/InterfaceTest/python_excel/utils/operation_json.py] [get_data_for_key ][/home/ma/PycharmProjects/Auto_InterFace_GUI/InterfaceTest/python_excel/utils/operation_json.py:39]- 操作JSON类根据key获取value异常，异常原因：'NoneType' object is not subscriptable
2019-09-18 16:28:54,936 [ERROR] [/home/ma/PycharmProjects/Auto_InterFace_GUI/InterfaceTest/python_excel/utils/operation_json.py] [read_data ][/home/ma/PycharmProjects/Auto_InterFace_GUI/InterfaceTest/python_excel/utils/operation_json.py:25]- 操作JSON类读取数据异常，异常原因：Extra data: line 5 column 2 (char 391)
2019-09-18 16:28:54,936 [ERROR] [/home/ma/PycharmProjects/Auto_InterFace_GUI/InterfaceTest/python_excel/utils/operation_json.py] [get_data_for_key ][/home/ma/PycharmProjects/Auto_InterFace_GUI/InterfaceTest/python_excel/utils/operation_json.py:39]- 操作JSON类根据key获取value异常，异常原因：'NoneType' object is not subscriptable
2019-09-18 16:28:54,936 [ERROR] [/home/ma/PycharmProjects/Auto_InterFace_GUI/InterfaceTest/python_excel/utils/operation_json.py] [read_data ][/home/ma/PycharmProjects/Auto_InterFace_GUI/InterfaceTest/python_excel/utils/operation_json.py:25]- 操作JSON类读取数据异常，异常原因：Extra data: line 5 column 2 (char 391)
2019-09-18 16:28:54,936 [ERROR] [/home/ma/PycharmProjects/Auto_InterFace_GUI/InterfaceTest/python_excel/utils/operation_json.py] [get_data_for_key ][/home/ma/PycharmProjects/Auto_InterFace_GUI/InterfaceTest/python_excel/utils/operation_json.py:39]- 操作JSON类根据key获取value异常，异常原因：'NoneType' object is not subscriptable
2019-09-18 16:28:54,937 [ERROR] [/home/ma/PycharmProjects/Auto_InterFace_GUI/InterfaceTest/python_excel/utils/operation_cfg.py] [read_cfg ][__file__:31]- 读取cfg配置文件内容异常，异常原因：'NoneType' object is not iterable
2019-09-18 16:28:54,937 [ERROR] [/home/ma/PycharmProjects/Auto_InterFace_GUI/InterfaceTest/python_excel/utils/operation_cfg.py] [get_section_option_list ][__file__:82]- 读取配置文件指定段section下所有option列表出现异常，异常原因：No section: 'my_case_file'
2019-09-18 16:28:57,315 [ERROR] [/home/ma/PycharmProjects/Auto_InterFace_GUI/venv/lib/python3.6/site-packages/django/utils/log.py] [log_response ][django.request:228]- Internal Server Error: /
Traceback (most recent call last):
  File "/home/ma/PycharmProjects/Auto_InterFace_GUI/venv/lib/python3.6/site-packages/django/core/handlers/exception.py", line 34, in inner
    response = get_response(request)
  File "/home/ma/PycharmProjects/Auto_InterFace_GUI/venv/lib/python3.6/site-packages/django/core/handlers/base.py", line 115, in _get_response
    response = self.process_exception_by_middleware(e, request)
  File "/home/ma/PycharmProjects/Auto_InterFace_GUI/venv/lib/python3.6/site-packages/django/core/handlers/base.py", line 113, in _get_response
    response = wrapped_callback(request, *callback_args, **callback_kwargs)
  File "/home/ma/PycharmProjects/Auto_InterFace_GUI/upload_case/views.py", line 49, in index
    from upload_case import case_test_common
  File "/home/ma/PycharmProjects/Auto_InterFace_GUI/upload_case/case_test_common.py", line 37, in <module>
    filename = option_dict["case_filepath"]
KeyError: 'case_filepath'
2019-09-18 16:31:30,561 [ERROR] [/home/ma/PycharmProjects/Auto_InterFace_GUI/InterfaceTest/python_excel/get_data/param_global.py] [deal_param_name_tuple ][__file__:59]- 处理接口请求参数名出现异常，异常原因：list index out of range
2019-09-18 16:31:30,757 [ERROR] [/home/ma/PycharmProjects/Auto_InterFace_GUI/InterfaceTest/python_excel/get_data/param_global.py] [deal_param_name_tuple ][__file__:59]- 处理接口请求参数名出现异常，异常原因：list index out of range
2019-09-18 16:31:30,758 [ERROR] [/home/ma/PycharmProjects/Auto_InterFace_GUI/InterfaceTest/python_excel/get_data/param_global.py] [deal_param_name_tuple ][__file__:59]- 处理接口请求参数名出现异常，异常原因：list index out of range
2019-09-18 16:31:34,946 [ERROR] [/home/ma/PycharmProjects/Auto_InterFace_GUI/InterfaceTest/python_excel/get_data/param_global.py] [deal_param_name_tuple ][__file__:59]- 处理接口请求参数名出现异常，异常原因：list index out of range
2019-09-18 16:31:55,443 [INFO] [/home/ma/PycharmProjects/Auto_InterFace_GUI/venv/lib/python3.6/site-packages/elasticsearch/connection/base.py] [log_request_success ][elasticsearch:121]- GET http://39.107.66.190:9200/evidence/_search [status:200 request:0.051s]
2019-09-18 16:33:59,517 [ERROR] [/home/ma/PycharmProjects/Auto_InterFace_GUI/InterfaceTest/python_excel/utils/operation_json.py] [read_data ][/home/ma/PycharmProjects/Auto_InterFace_GUI/InterfaceTest/python_excel/utils/operation_json.py:25]- 操作JSON类读取数据异常，异常原因：Extra data: line 5 column 2 (char 390)
2019-09-18 16:33:59,518 [ERROR] [/home/ma/PycharmProjects/Auto_InterFace_GUI/InterfaceTest/python_excel/utils/operation_json.py] [read_data ][/home/ma/PycharmProjects/Auto_InterFace_GUI/InterfaceTest/python_excel/utils/operation_json.py:25]- 操作JSON类读取数据异常，异常原因：Extra data: line 5 column 2 (char 390)
2019-09-18 16:33:59,518 [ERROR] [/home/ma/PycharmProjects/Auto_InterFace_GUI/InterfaceTest/python_excel/utils/operation_json.py] [get_data_for_key ][/home/ma/PycharmProjects/Auto_InterFace_GUI/InterfaceTest/python_excel/utils/operation_json.py:39]- 操作JSON类根据key获取value异常，异常原因：'NoneType' object is not subscriptable
2019-09-18 16:33:59,519 [ERROR] [/home/ma/PycharmProjects/Auto_InterFace_GUI/InterfaceTest/python_excel/utils/operation_json.py] [read_data ][/home/ma/PycharmProjects/Auto_InterFace_GUI/InterfaceTest/python_excel/utils/operation_json.py:25]- 操作JSON类读取数据异常，异常原因：Extra data: line 5 column 2 (char 390)
2019-09-18 16:33:59,519 [ERROR] [/home/ma/PycharmProjects/Auto_InterFace_GUI/InterfaceTest/python_excel/utils/operation_json.py] [get_data_for_key ][/home/ma/PycharmProjects/Auto_InterFace_GUI/InterfaceTest/python_excel/utils/operation_json.py:39]- 操作JSON类根据key获取value异常，异常原因：'NoneType' object is not subscriptable
2019-09-18 16:33:59,519 [ERROR] [/home/ma/PycharmProjects/Auto_InterFace_GUI/InterfaceTest/python_excel/utils/operation_json.py] [read_data ][/home/ma/PycharmProjects/Auto_InterFace_GUI/InterfaceTest/python_excel/utils/operation_json.py:25]- 操作JSON类读取数据异常，异常原因：Extra data: line 5 column 2 (char 390)
2019-09-18 16:33:59,519 [ERROR] [/home/ma/PycharmProjects/Auto_InterFace_GUI/InterfaceTest/python_excel/utils/operation_json.py] [get_data_for_key ][/home/ma/PycharmProjects/Auto_InterFace_GUI/InterfaceTest/python_excel/utils/operation_json.py:39]- 操作JSON类根据key获取value异常，异常原因：'NoneType' object is not subscriptable
2019-09-18 16:33:59,520 [ERROR] [/home/ma/PycharmProjects/Auto_InterFace_GUI/InterfaceTest/python_excel/utils/operation_cfg.py] [read_cfg ][__file__:31]- 读取cfg配置文件内容异常，异常原因：'NoneType' object is not iterable
2019-09-18 16:33:59,520 [ERROR] [/home/ma/PycharmProjects/Auto_InterFace_GUI/InterfaceTest/python_excel/utils/operation_cfg.py] [get_section_option_list ][__file__:82]- 读取配置文件指定段section下所有option列表出现异常，异常原因：No section: 'my_case_file'
2019-09-18 16:34:01,748 [ERROR] [/home/ma/PycharmProjects/Auto_InterFace_GUI/venv/lib/python3.6/site-packages/django/utils/log.py] [log_response ][django.request:228]- Internal Server Error: /
Traceback (most recent call last):
  File "/home/ma/PycharmProjects/Auto_InterFace_GUI/venv/lib/python3.6/site-packages/django/core/handlers/exception.py", line 34, in inner
    response = get_response(request)
  File "/home/ma/PycharmProjects/Auto_InterFace_GUI/venv/lib/python3.6/site-packages/django/core/handlers/base.py", line 115, in _get_response
    response = self.process_exception_by_middleware(e, request)
  File "/home/ma/PycharmProjects/Auto_InterFace_GUI/venv/lib/python3.6/site-packages/django/core/handlers/base.py", line 113, in _get_response
    response = wrapped_callback(request, *callback_args, **callback_kwargs)
  File "/home/ma/PycharmProjects/Auto_InterFace_GUI/upload_case/views.py", line 49, in index
    from upload_case import case_test_common
  File "/home/ma/PycharmProjects/Auto_InterFace_GUI/upload_case/case_test_common.py", line 37, in <module>
    filename = option_dict["case_filepath"]
KeyError: 'case_filepath'
2019-09-18 16:34:01,961 [WARNING] [/home/ma/PycharmProjects/Auto_InterFace_GUI/venv/lib/python3.6/site-packages/django/utils/log.py] [log_response ][django.request:228]- Not Found: /favicon.ico
2019-09-18 16:40:50,995 [ERROR] [/home/ma/PycharmProjects/Auto_InterFace_GUI/InterfaceTest/python_excel/utils/operation_json.py] [read_data ][/home/ma/PycharmProjects/Auto_InterFace_GUI/InterfaceTest/python_excel/utils/operation_json.py:25]- 操作JSON类读取数据异常，异常原因：Extra data: line 5 column 2 (char 390)
2019-09-18 16:40:50,996 [ERROR] [/home/ma/PycharmProjects/Auto_InterFace_GUI/InterfaceTest/python_excel/utils/operation_json.py] [read_data ][/home/ma/PycharmProjects/Auto_InterFace_GUI/InterfaceTest/python_excel/utils/operation_json.py:25]- 操作JSON类读取数据异常，异常原因：Extra data: line 5 column 2 (char 390)
2019-09-18 16:40:50,996 [ERROR] [/home/ma/PycharmProjects/Auto_InterFace_GUI/InterfaceTest/python_excel/utils/operation_json.py] [get_data_for_key ][/home/ma/PycharmProjects/Auto_InterFace_GUI/InterfaceTest/python_excel/utils/operation_json.py:39]- 操作JSON类根据key获取value异常，异常原因：'NoneType' object is not subscriptable
2019-09-18 16:40:50,996 [ERROR] [/home/ma/PycharmProjects/Auto_InterFace_GUI/InterfaceTest/python_excel/utils/operation_json.py] [read_data ][/home/ma/PycharmProjects/Auto_InterFace_GUI/InterfaceTest/python_excel/utils/operation_json.py:25]- 操作JSON类读取数据异常，异常原因：Extra data: line 5 column 2 (char 390)
2019-09-18 16:40:50,996 [ERROR] [/home/ma/PycharmProjects/Auto_InterFace_GUI/InterfaceTest/python_excel/utils/operation_json.py] [get_data_for_key ][/home/ma/PycharmProjects/Auto_InterFace_GUI/InterfaceTest/python_excel/utils/operation_json.py:39]- 操作JSON类根据key获取value异常，异常原因：'NoneType' object is not subscriptable
2019-09-18 16:40:50,997 [ERROR] [/home/ma/PycharmProjects/Auto_InterFace_GUI/InterfaceTest/python_excel/utils/operation_json.py] [read_data ][/home/ma/PycharmProjects/Auto_InterFace_GUI/InterfaceTest/python_excel/utils/operation_json.py:25]- 操作JSON类读取数据异常，异常原因：Extra data: line 5 column 2 (char 390)
2019-09-18 16:40:50,997 [ERROR] [/home/ma/PycharmProjects/Auto_InterFace_GUI/InterfaceTest/python_excel/utils/operation_json.py] [get_data_for_key ][/home/ma/PycharmProjects/Auto_InterFace_GUI/InterfaceTest/python_excel/utils/operation_json.py:39]- 操作JSON类根据key获取value异常，异常原因：'NoneType' object is not subscriptable
2019-09-18 16:40:50,997 [ERROR] [/home/ma/PycharmProjects/Auto_InterFace_GUI/InterfaceTest/python_excel/utils/operation_cfg.py] [read_cfg ][__file__:31]- 读取cfg配置文件内容异常，异常原因：'NoneType' object is not iterable
2019-09-18 16:40:50,997 [ERROR] [/home/ma/PycharmProjects/Auto_InterFace_GUI/InterfaceTest/python_excel/utils/operation_cfg.py] [get_section_option_list ][__file__:82]- 读取配置文件指定段section下所有option列表出现异常，异常原因：No section: 'my_case_file'
2019-09-18 16:40:53,425 [ERROR] [/home/ma/PycharmProjects/Auto_InterFace_GUI/venv/lib/python3.6/site-packages/django/utils/log.py] [log_response ][django.request:228]- Internal Server Error: /
Traceback (most recent call last):
  File "/home/ma/PycharmProjects/Auto_InterFace_GUI/venv/lib/python3.6/site-packages/django/core/handlers/exception.py", line 34, in inner
    response = get_response(request)
  File "/home/ma/PycharmProjects/Auto_InterFace_GUI/venv/lib/python3.6/site-packages/django/core/handlers/base.py", line 115, in _get_response
    response = self.process_exception_by_middleware(e, request)
  File "/home/ma/PycharmProjects/Auto_InterFace_GUI/venv/lib/python3.6/site-packages/django/core/handlers/base.py", line 113, in _get_response
    response = wrapped_callback(request, *callback_args, **callback_kwargs)
  File "/home/ma/PycharmProjects/Auto_InterFace_GUI/upload_case/views.py", line 49, in index
    from upload_case import case_test_common
  File "/home/ma/PycharmProjects/Auto_InterFace_GUI/upload_case/case_test_common.py", line 37, in <module>
    filename = option_dict["case_filepath"]
KeyError: 'case_filepath'
2019-09-18 16:43:08,513 [ERROR] [/home/ma/PycharmProjects/Auto_InterFace_GUI/InterfaceTest/python_excel/get_data/param_global.py] [deal_param_name_tuple ][__file__:59]- 处理接口请求参数名出现异常，异常原因：list index out of range
2019-09-18 16:43:08,672 [ERROR] [/home/ma/PycharmProjects/Auto_InterFace_GUI/InterfaceTest/python_excel/get_data/param_global.py] [deal_param_name_tuple ][__file__:59]- 处理接口请求参数名出现异常，异常原因：list index out of range
2019-09-18 16:43:08,673 [ERROR] [/home/ma/PycharmProjects/Auto_InterFace_GUI/InterfaceTest/python_excel/get_data/param_global.py] [deal_param_name_tuple ][__file__:59]- 处理接口请求参数名出现异常，异常原因：list index out of range
2019-09-18 16:43:09,654 [ERROR] [/home/ma/PycharmProjects/Auto_InterFace_GUI/InterfaceTest/python_excel/get_data/param_global.py] [deal_param_name_tuple ][__file__:59]- 处理接口请求参数名出现异常，异常原因：list index out of range
2019-09-18 16:43:19,562 [INFO] [/home/ma/PycharmProjects/Auto_InterFace_GUI/venv/lib/python3.6/site-packages/elasticsearch/connection/base.py] [log_request_success ][elasticsearch:121]- GET http://39.107.66.190:9200/evidence/_search [status:200 request:0.048s]
2019-09-18 16:44:33,151 [INFO] [/home/ma/PycharmProjects/Auto_InterFace_GUI/venv/lib/python3.6/site-packages/django/utils/autoreload.py] [trigger_reload ][django.utils.autoreload:217]- /home/ma/PycharmProjects/Auto_InterFace_GUI/InterfaceTest/python_excel/common/cmp_res_req.py changed, reloading.
2019-09-18 17:49:54,866 [ERROR] [/home/ma/PycharmProjects/Auto_InterFace_GUI/InterfaceTest/python_excel/get_data/param_global.py] [deal_param_name_tuple ][__file__:59]- 处理接口请求参数名出现异常，异常原因：list index out of range
2019-09-18 17:49:55,027 [ERROR] [/home/ma/PycharmProjects/Auto_InterFace_GUI/InterfaceTest/python_excel/get_data/param_global.py] [deal_param_name_tuple ][__file__:59]- 处理接口请求参数名出现异常，异常原因：list index out of range
2019-09-18 17:49:55,028 [ERROR] [/home/ma/PycharmProjects/Auto_InterFace_GUI/InterfaceTest/python_excel/get_data/param_global.py] [deal_param_name_tuple ][__file__:59]- 处理接口请求参数名出现异常，异常原因：list index out of range
2019-09-18 17:50:12,306 [ERROR] [/home/ma/PycharmProjects/Auto_InterFace_GUI/InterfaceTest/python_excel/get_data/param_global.py] [deal_param_name_tuple ][__file__:59]- 处理接口请求参数名出现异常，异常原因：list index out of range
2019-09-18 17:50:21,682 [INFO] [/home/ma/PycharmProjects/Auto_InterFace_GUI/venv/lib/python3.6/site-packages/elasticsearch/connection/base.py] [log_request_success ][elasticsearch:121]- GET http://39.107.66.190:9200/evidence/_search [status:200 request:0.051s]
2019-09-18 17:51:39,770 [ERROR] [/home/ma/PycharmProjects/Auto_InterFace_GUI/InterfaceTest/python_excel/get_data/param_global.py] [deal_param_name_tuple ][__file__:59]- 处理接口请求参数名出现异常，异常原因：list index out of range
2019-09-18 17:51:39,862 [ERROR] [/home/ma/PycharmProjects/Auto_InterFace_GUI/InterfaceTest/python_excel/get_data/param_global.py] [deal_param_name_tuple ][__file__:59]- 处理接口请求参数名出现异常，异常原因：list index out of range
2019-09-18 17:51:39,862 [ERROR] [/home/ma/PycharmProjects/Auto_InterFace_GUI/InterfaceTest/python_excel/get_data/param_global.py] [deal_param_name_tuple ][__file__:59]- 处理接口请求参数名出现异常，异常原因：list index out of range
2019-09-18 17:51:39,864 [ERROR] [/home/ma/PycharmProjects/Auto_InterFace_GUI/InterfaceTest/python_excel/get_data/param_global.py] [deal_param_name_tuple ][__file__:59]- 处理接口请求参数名出现异常，异常原因：list index out of range
2019-09-18 17:51:40,050 [INFO] [/home/ma/PycharmProjects/Auto_InterFace_GUI/venv/lib/python3.6/site-packages/elasticsearch/connection/base.py] [log_request_success ][elasticsearch:121]- GET http://39.107.66.190:9200/evidence/_search [status:200 request:0.049s]
2019-09-18 17:52:19,516 [ERROR] [/home/ma/PycharmProjects/Auto_InterFace_GUI/InterfaceTest/python_excel/get_data/param_global.py] [deal_param_name_tuple ][__file__:59]- 处理接口请求参数名出现异常，异常原因：list index out of range
2019-09-18 17:52:19,692 [INFO] [/home/ma/PycharmProjects/Auto_InterFace_GUI/venv/lib/python3.6/site-packages/elasticsearch/connection/base.py] [log_request_success ][elasticsearch:121]- GET http://39.107.66.190:9200/evidence/_search [status:200 request:0.050s]
2019-09-18 17:52:52,962 [ERROR] [/home/ma/PycharmProjects/Auto_InterFace_GUI/InterfaceTest/python_excel/get_data/param_global.py] [deal_param_name_tuple ][__file__:59]- 处理接口请求参数名出现异常，异常原因：list index out of range
2019-09-18 17:52:53,141 [INFO] [/home/ma/PycharmProjects/Auto_InterFace_GUI/venv/lib/python3.6/site-packages/elasticsearch/connection/base.py] [log_request_success ][elasticsearch:121]- GET http://39.107.66.190:9200/evidence/_search [status:200 request:0.050s]
2019-09-18 17:53:36,027 [ERROR] [/home/ma/PycharmProjects/Auto_InterFace_GUI/InterfaceTest/python_excel/get_data/param_global.py] [deal_param_name_tuple ][__file__:59]- 处理接口请求参数名出现异常，异常原因：list index out of range
2019-09-18 17:53:36,230 [INFO] [/home/ma/PycharmProjects/Auto_InterFace_GUI/venv/lib/python3.6/site-packages/elasticsearch/connection/base.py] [log_request_success ][elasticsearch:121]- GET http://39.107.66.190:9200/evidence/_search [status:200 request:0.049s]
2019-09-18 17:55:25,372 [ERROR] [/home/ma/PycharmProjects/Auto_InterFace_GUI/InterfaceTest/python_excel/get_data/param_global.py] [deal_param_name_tuple ][__file__:59]- 处理接口请求参数名出现异常，异常原因：list index out of range
2019-09-18 17:55:25,557 [INFO] [/home/ma/PycharmProjects/Auto_InterFace_GUI/venv/lib/python3.6/site-packages/elasticsearch/connection/base.py] [log_request_success ][elasticsearch:121]- GET http://39.107.66.190:9200/evidence/_search [status:200 request:0.047s]
2019-09-18 17:57:11,357 [ERROR] [/home/ma/PycharmProjects/Auto_InterFace_GUI/InterfaceTest/python_excel/utils/operation_json.py] [read_data ][/home/ma/PycharmProjects/Auto_InterFace_GUI/InterfaceTest/python_excel/utils/operation_json.py:25]- 操作JSON类读取数据异常，异常原因：Extra data: line 5 column 2 (char 390)
2019-09-18 17:57:11,358 [ERROR] [/home/ma/PycharmProjects/Auto_InterFace_GUI/InterfaceTest/python_excel/utils/operation_json.py] [read_data ][/home/ma/PycharmProjects/Auto_InterFace_GUI/InterfaceTest/python_excel/utils/operation_json.py:25]- 操作JSON类读取数据异常，异常原因：Extra data: line 5 column 2 (char 390)
2019-09-18 17:57:11,358 [ERROR] [/home/ma/PycharmProjects/Auto_InterFace_GUI/InterfaceTest/python_excel/utils/operation_json.py] [get_data_for_key ][/home/ma/PycharmProjects/Auto_InterFace_GUI/InterfaceTest/python_excel/utils/operation_json.py:39]- 操作JSON类根据key获取value异常，异常原因：'NoneType' object is not subscriptable
2019-09-18 17:57:11,358 [ERROR] [/home/ma/PycharmProjects/Auto_InterFace_GUI/InterfaceTest/python_excel/utils/operation_json.py] [read_data ][/home/ma/PycharmProjects/Auto_InterFace_GUI/InterfaceTest/python_excel/utils/operation_json.py:25]- 操作JSON类读取数据异常，异常原因：Extra data: line 5 column 2 (char 390)
2019-09-18 17:57:11,358 [ERROR] [/home/ma/PycharmProjects/Auto_InterFace_GUI/InterfaceTest/python_excel/utils/operation_json.py] [get_data_for_key ][/home/ma/PycharmProjects/Auto_InterFace_GUI/InterfaceTest/python_excel/utils/operation_json.py:39]- 操作JSON类根据key获取value异常，异常原因：'NoneType' object is not subscriptable
2019-09-18 17:57:11,358 [ERROR] [/home/ma/PycharmProjects/Auto_InterFace_GUI/InterfaceTest/python_excel/utils/operation_json.py] [read_data ][/home/ma/PycharmProjects/Auto_InterFace_GUI/InterfaceTest/python_excel/utils/operation_json.py:25]- 操作JSON类读取数据异常，异常原因：Extra data: line 5 column 2 (char 390)
2019-09-18 17:57:11,359 [ERROR] [/home/ma/PycharmProjects/Auto_InterFace_GUI/InterfaceTest/python_excel/utils/operation_json.py] [get_data_for_key ][/home/ma/PycharmProjects/Auto_InterFace_GUI/InterfaceTest/python_excel/utils/operation_json.py:39]- 操作JSON类根据key获取value异常，异常原因：'NoneType' object is not subscriptable
2019-09-18 17:57:11,359 [ERROR] [/home/ma/PycharmProjects/Auto_InterFace_GUI/InterfaceTest/python_excel/utils/operation_cfg.py] [read_cfg ][__file__:31]- 读取cfg配置文件内容异常，异常原因：'NoneType' object is not iterable
2019-09-18 17:57:11,359 [ERROR] [/home/ma/PycharmProjects/Auto_InterFace_GUI/InterfaceTest/python_excel/utils/operation_cfg.py] [get_section_option_list ][__file__:82]- 读取配置文件指定段section下所有option列表出现异常，异常原因：No section: 'my_case_file'
2019-09-18 17:57:12,936 [ERROR] [/home/ma/PycharmProjects/Auto_InterFace_GUI/venv/lib/python3.6/site-packages/django/utils/log.py] [log_response ][django.request:228]- Internal Server Error: /
Traceback (most recent call last):
  File "/home/ma/PycharmProjects/Auto_InterFace_GUI/venv/lib/python3.6/site-packages/django/core/handlers/exception.py", line 34, in inner
    response = get_response(request)
  File "/home/ma/PycharmProjects/Auto_InterFace_GUI/venv/lib/python3.6/site-packages/django/core/handlers/base.py", line 115, in _get_response
    response = self.process_exception_by_middleware(e, request)
  File "/home/ma/PycharmProjects/Auto_InterFace_GUI/venv/lib/python3.6/site-packages/django/core/handlers/base.py", line 113, in _get_response
    response = wrapped_callback(request, *callback_args, **callback_kwargs)
  File "/home/ma/PycharmProjects/Auto_InterFace_GUI/upload_case/views.py", line 49, in index
    from upload_case import case_test_common
  File "/home/ma/PycharmProjects/Auto_InterFace_GUI/upload_case/case_test_common.py", line 37, in <module>
    filename = option_dict["case_filepath"]
KeyError: 'case_filepath'
2019-09-18 17:57:30,004 [ERROR] [/home/ma/PycharmProjects/Auto_InterFace_GUI/InterfaceTest/python_excel/get_data/param_global.py] [deal_param_name_tuple ][__file__:59]- 处理接口请求参数名出现异常，异常原因：list index out of range
2019-09-18 17:57:30,098 [ERROR] [/home/ma/PycharmProjects/Auto_InterFace_GUI/InterfaceTest/python_excel/get_data/param_global.py] [deal_param_name_tuple ][__file__:59]- 处理接口请求参数名出现异常，异常原因：list index out of range
2019-09-18 17:57:30,098 [ERROR] [/home/ma/PycharmProjects/Auto_InterFace_GUI/InterfaceTest/python_excel/get_data/param_global.py] [deal_param_name_tuple ][__file__:59]- 处理接口请求参数名出现异常，异常原因：list index out of range
2019-09-18 17:57:30,100 [ERROR] [/home/ma/PycharmProjects/Auto_InterFace_GUI/InterfaceTest/python_excel/get_data/param_global.py] [deal_param_name_tuple ][__file__:59]- 处理接口请求参数名出现异常，异常原因：list index out of range
2019-09-18 17:57:30,263 [INFO] [/home/ma/PycharmProjects/Auto_InterFace_GUI/venv/lib/python3.6/site-packages/elasticsearch/connection/base.py] [log_request_success ][elasticsearch:121]- GET http://39.107.66.190:9200/evidence/_search [status:200 request:0.050s]
2019-09-18 17:58:37,882 [ERROR] [/home/ma/PycharmProjects/Auto_InterFace_GUI/InterfaceTest/python_excel/get_data/param_global.py] [deal_param_name_tuple ][__file__:59]- 处理接口请求参数名出现异常，异常原因：list index out of range
2019-09-18 17:58:38,064 [INFO] [/home/ma/PycharmProjects/Auto_InterFace_GUI/venv/lib/python3.6/site-packages/elasticsearch/connection/base.py] [log_request_success ][elasticsearch:121]- GET http://39.107.66.190:9200/evidence/_search [status:200 request:0.048s]
2019-09-18 17:58:59,063 [ERROR] [/home/ma/PycharmProjects/Auto_InterFace_GUI/InterfaceTest/python_excel/get_data/param_global.py] [deal_param_name_tuple ][__file__:59]- 处理接口请求参数名出现异常，异常原因：list index out of range
2019-09-18 17:58:59,219 [INFO] [/home/ma/PycharmProjects/Auto_InterFace_GUI/venv/lib/python3.6/site-packages/elasticsearch/connection/base.py] [log_request_success ][elasticsearch:121]- GET http://39.107.66.190:9200/evidence/_search [status:200 request:0.048s]
2019-09-18 18:01:51,692 [ERROR] [/home/ma/PycharmProjects/Auto_InterFace_GUI/InterfaceTest/python_excel/utils/operation_json.py] [read_data ][/home/ma/PycharmProjects/Auto_InterFace_GUI/InterfaceTest/python_excel/utils/operation_json.py:25]- 操作JSON类读取数据异常，异常原因：Extra data: line 5 column 2 (char 390)
2019-09-18 18:01:51,693 [ERROR] [/home/ma/PycharmProjects/Auto_InterFace_GUI/InterfaceTest/python_excel/utils/operation_json.py] [read_data ][/home/ma/PycharmProjects/Auto_InterFace_GUI/InterfaceTest/python_excel/utils/operation_json.py:25]- 操作JSON类读取数据异常，异常原因：Extra data: line 5 column 2 (char 390)
2019-09-18 18:01:51,693 [ERROR] [/home/ma/PycharmProjects/Auto_InterFace_GUI/InterfaceTest/python_excel/utils/operation_json.py] [get_data_for_key ][/home/ma/PycharmProjects/Auto_InterFace_GUI/InterfaceTest/python_excel/utils/operation_json.py:39]- 操作JSON类根据key获取value异常，异常原因：'NoneType' object is not subscriptable
2019-09-18 18:01:51,693 [ERROR] [/home/ma/PycharmProjects/Auto_InterFace_GUI/InterfaceTest/python_excel/utils/operation_json.py] [read_data ][/home/ma/PycharmProjects/Auto_InterFace_GUI/InterfaceTest/python_excel/utils/operation_json.py:25]- 操作JSON类读取数据异常，异常原因：Extra data: line 5 column 2 (char 390)
2019-09-18 18:01:51,693 [ERROR] [/home/ma/PycharmProjects/Auto_InterFace_GUI/InterfaceTest/python_excel/utils/operation_json.py] [get_data_for_key ][/home/ma/PycharmProjects/Auto_InterFace_GUI/InterfaceTest/python_excel/utils/operation_json.py:39]- 操作JSON类根据key获取value异常，异常原因：'NoneType' object is not subscriptable
2019-09-18 18:01:51,693 [ERROR] [/home/ma/PycharmProjects/Auto_InterFace_GUI/InterfaceTest/python_excel/utils/operation_json.py] [read_data ][/home/ma/PycharmProjects/Auto_InterFace_GUI/InterfaceTest/python_excel/utils/operation_json.py:25]- 操作JSON类读取数据异常，异常原因：Extra data: line 5 column 2 (char 390)
2019-09-18 18:01:51,693 [ERROR] [/home/ma/PycharmProjects/Auto_InterFace_GUI/InterfaceTest/python_excel/utils/operation_json.py] [get_data_for_key ][/home/ma/PycharmProjects/Auto_InterFace_GUI/InterfaceTest/python_excel/utils/operation_json.py:39]- 操作JSON类根据key获取value异常，异常原因：'NoneType' object is not subscriptable
2019-09-18 18:01:51,694 [ERROR] [/home/ma/PycharmProjects/Auto_InterFace_GUI/InterfaceTest/python_excel/utils/operation_cfg.py] [read_cfg ][__file__:31]- 读取cfg配置文件内容异常，异常原因：'NoneType' object is not iterable
2019-09-18 18:01:51,694 [ERROR] [/home/ma/PycharmProjects/Auto_InterFace_GUI/InterfaceTest/python_excel/utils/operation_cfg.py] [get_section_option_list ][__file__:82]- 读取配置文件指定段section下所有option列表出现异常，异常原因：No section: 'my_case_file'
2019-09-18 18:01:55,881 [ERROR] [/home/ma/PycharmProjects/Auto_InterFace_GUI/venv/lib/python3.6/site-packages/django/utils/log.py] [log_response ][django.request:228]- Internal Server Error: /
Traceback (most recent call last):
  File "/home/ma/PycharmProjects/Auto_InterFace_GUI/venv/lib/python3.6/site-packages/django/core/handlers/exception.py", line 34, in inner
    response = get_response(request)
  File "/home/ma/PycharmProjects/Auto_InterFace_GUI/venv/lib/python3.6/site-packages/django/core/handlers/base.py", line 115, in _get_response
    response = self.process_exception_by_middleware(e, request)
  File "/home/ma/PycharmProjects/Auto_InterFace_GUI/venv/lib/python3.6/site-packages/django/core/handlers/base.py", line 113, in _get_response
    response = wrapped_callback(request, *callback_args, **callback_kwargs)
  File "/home/ma/PycharmProjects/Auto_InterFace_GUI/upload_case/views.py", line 49, in index
    from upload_case import case_test_common
  File "/home/ma/PycharmProjects/Auto_InterFace_GUI/upload_case/case_test_common.py", line 37, in <module>
    filename = option_dict["case_filepath"]
KeyError: 'case_filepath'
2019-09-18 18:02:41,538 [ERROR] [/home/ma/PycharmProjects/Auto_InterFace_GUI/InterfaceTest/python_excel/get_data/param_global.py] [deal_param_name_tuple ][__file__:59]- 处理接口请求参数名出现异常，异常原因：list index out of range
2019-09-18 18:02:41,724 [ERROR] [/home/ma/PycharmProjects/Auto_InterFace_GUI/InterfaceTest/python_excel/get_data/param_global.py] [deal_param_name_tuple ][__file__:59]- 处理接口请求参数名出现异常，异常原因：list index out of range
2019-09-18 18:02:41,725 [ERROR] [/home/ma/PycharmProjects/Auto_InterFace_GUI/InterfaceTest/python_excel/get_data/param_global.py] [deal_param_name_tuple ][__file__:59]- 处理接口请求参数名出现异常，异常原因：list index out of range
2019-09-18 18:02:44,090 [ERROR] [/home/ma/PycharmProjects/Auto_InterFace_GUI/InterfaceTest/python_excel/get_data/param_global.py] [deal_param_name_tuple ][__file__:59]- 处理接口请求参数名出现异常，异常原因：list index out of range
2019-09-18 18:02:49,790 [INFO] [/home/ma/PycharmProjects/Auto_InterFace_GUI/venv/lib/python3.6/site-packages/elasticsearch/connection/base.py] [log_request_success ][elasticsearch:121]- GET http://39.107.66.190:9200/evidence/_search [status:200 request:0.050s]
2019-09-18 18:05:01,469 [ERROR] [/home/ma/PycharmProjects/Auto_InterFace_GUI/InterfaceTest/python_excel/get_data/param_global.py] [deal_param_name_tuple ][__file__:59]- 处理接口请求参数名出现异常，异常原因：list index out of range
2019-09-18 18:05:02,914 [INFO] [/home/ma/PycharmProjects/Auto_InterFace_GUI/venv/lib/python3.6/site-packages/elasticsearch/connection/base.py] [log_request_success ][elasticsearch:121]- GET http://39.107.66.190:9200/evidence/_search [status:200 request:0.052s]
2019-09-18 18:06:28,883 [ERROR] [/home/ma/PycharmProjects/Auto_InterFace_GUI/InterfaceTest/python_excel/get_data/param_global.py] [deal_param_name_tuple ][__file__:59]- 处理接口请求参数名出现异常，异常原因：list index out of range
2019-09-18 18:06:29,077 [ERROR] [/home/ma/PycharmProjects/Auto_InterFace_GUI/InterfaceTest/python_excel/get_data/param_global.py] [deal_param_name_tuple ][__file__:59]- 处理接口请求参数名出现异常，异常原因：list index out of range
2019-09-18 18:06:29,077 [ERROR] [/home/ma/PycharmProjects/Auto_InterFace_GUI/InterfaceTest/python_excel/get_data/param_global.py] [deal_param_name_tuple ][__file__:59]- 处理接口请求参数名出现异常，异常原因：list index out of range
2019-09-18 18:06:29,079 [ERROR] [/home/ma/PycharmProjects/Auto_InterFace_GUI/InterfaceTest/python_excel/get_data/param_global.py] [deal_param_name_tuple ][__file__:59]- 处理接口请求参数名出现异常，异常原因：list index out of range
2019-09-18 18:06:29,271 [INFO] [/home/ma/PycharmProjects/Auto_InterFace_GUI/venv/lib/python3.6/site-packages/elasticsearch/connection/base.py] [log_request_success ][elasticsearch:121]- GET http://39.107.66.190:9200/evidence/_search [status:200 request:0.049s]
2019-09-18 18:06:29,276 [ERROR] [/home/ma/PycharmProjects/Auto_InterFace_GUI/InterfaceTest/python_excel/get_data/param_global.py] [deal_param_name_tuple ][__file__:59]- 处理接口请求参数名出现异常，异常原因：list index out of range
2019-09-18 18:06:29,432 [INFO] [/home/ma/PycharmProjects/Auto_InterFace_GUI/venv/lib/python3.6/site-packages/elasticsearch/connection/base.py] [log_request_success ][elasticsearch:121]- GET http://39.107.66.190:9200/evidence/_search [status:200 request:0.048s]
